Workbook

Sheet Sheet1
B2: Internal Memo | K2: No.
B3: To : | C3: ผู้จัดการเขต / ผู้จัดการสาขา | K3: Date :
B4: RE : | C4: ราคาขาย เดือน
G6: W1 | I6: W2 | K6: W | M6: R
C7: ชื่อสินค้า | D7: RE | E7: RE inv. | I7: ร้านค้าส่งทั่วไป | M7: ขายปลีก
A8: 1 | C8: 1. โครงซีลายน์ - โรงงานทีรกร
B9: 0.525 | C9: ทีรกร ซีลายน์ 5.0-5.5 กก. | G9: 17.75 | H9: =G9/$E9-1 -> #DIV/0! | I9: 18.5 | J9: =I9/$E9-1 -> #DIV/0! | K9: 19 | L9: =K9/$E9-1 -> #DIV/0! | M9: 20.25 | N9: =M9/$E9-1 -> #DIV/0!
B10: 0.575 | C10: ทีรกร ซีลายน์ 5.6-5.9 กก. | G10: 19.5 | H10: =G10/$E10-1 -> #DIV/0! | I10: 20.25 | J10: =I10/$E10-1 -> #DIV/0! | K10: 20.75 | L10: =K10/$E10-1 -> #DIV/0! | M10: 22 | N10: =M10/$E10-1 -> #DIV/0!
B11: 0.625 | C11: ทีรกร ซีลายน์ 6.0-6.5 กก. | G11: 21 | H11: =G11/$E11-1 -> #DIV/0! | I11: 22 | J11: =I11/$E11-1 -> #DIV/0! | K11: 22.5 | L11: =K11/$E11-1 -> #DIV/0! | M11: 24 | N11: =M11/$E11-1 -> #DIV/0!
B12: 0.675 | C12: ทีรกร ซีลายน์ 6.6-6.9 กก. | G12: 22.75 | H12: =G12/$E12-1 -> #DIV/0! | I12: 23.75 | J12: =I12/$E12-1 -> #DIV/0! | K12: 24.5 | L12: =K12/$E12-1 -> #DIV/0! | M12: 26 | N12: =M12/$E12-1 -> #DIV/0!
B13: 0.725 | C13: ทีรกร ซีลายน์ 7.0-7.5 กก. | G13: 24.5 | H13: =G13/$E13-1 -> #DIV/0! | I13: 25.5 | J13: =I13/$E13-1 -> #DIV/0! | K13: 26.25 | L13: =K13/$E13-1 -> #DIV/0! | M13: 27.75 | N13: =M13/$E13-1 -> #DIV/0!
B14: 0.775 | C14: ทีรกร ซีลายน์ 7.6-7.9 กก. | G14: 26.25 | H14: =G14/$E14-1 -> #DIV/0! | I14: 27.25 | J14: =I14/$E14-1 -> #DIV/0! | K14: 28 | L14: =K14/$E14-1 -> #DIV/0! | M14: 29.75 | N14: =M14/$E14-1 -> #DIV/0!
B15: 0.825 | C15: ทีรกร ซีลายน์ 8.0-8.5 กก. | G15: 28 | H15: =G15/$E15-1 -> #DIV/0! | I15: 29 | J15: =I15/$E15-1 -> #DIV/0! | K15: 29.75 | L15: =K15/$E15-1 -> #DIV/0! | M15: 31.5 | N15: =M15/$E15-1 -> #DIV/0!
B16: 0.925 | C16: ทีรกร ซีลายน์ 9.0-9.5 กก. | G16: 31.5 | H16: =G16/$E16-1 -> #DIV/0! | I16: 32.5 | J16: =I16/$E16-1 -> #DIV/0! | K16: 33.5 | L16: =K16/$E16-1 -> #DIV/0! | M16: 35.25 | N16: =M16/$E16-1 -> #DIV/0!
B17: 1.025 | C17: ทีรกร ซีลายน์ 10.0-10.5 กก. | G17: 35 | H17: =G17/$E17-1 -> #DIV/0! | I17: 36 | J17: =I17/$E17-1 -> #DIV/0! | K17: 37 | L17: =K17/$E17-1 -> #DIV/0! | M17: 39 | N17: =M17/$E17-1 -> #DIV/0!
A19: 2 | C19: 1. โครงซีลายน์ - โรงงาน C&T
B20: 0.54 | C20: C&T ซีลายน์ 5.3-5.5 กก. | G20: 22 | H20: =G20/$E20-1 -> #DIV/0! | I20: 22.75 | J20: =I20/$E20-1 -> #DIV/0! | K20: 23.5 | L20: =K20/$E20-1 -> #DIV/0! | M20: 24.75 | N20: =M20/$E20-1 -> #DIV/0!
B21: 0.57 | C21: C&T ซีลายน์ 5.6-5.8 กก. | G21: 23.25 | H21: =G21/$E21-1 -> #DIV/0! | I21: 24 | J21: =I21/$E21-1 -> #DIV/0! | K21: 24.75 | L21: =K21/$E21-1 -> #DIV/0! | M21: 26.25 | N21: =M21/$E21-1 -> #DIV/0!
B22: 0.63 | C22: C&T ซีลายน์ 6.2-6.4 กก. | G22: 25.75 | H22: =G22/$E22-1 -> #DIV/0! | I22: 26.5 | J22: =I22/$E22-1 -> #DIV/0! | K22: 27.25 | L22: =K22/$E22-1 -> #DIV/0! | M22: 29 | N22: =M22/$E22-1 -> #DIV/0!
B23: 0.66 | C23: C&T ซีลายน์ 6.5-6.7 กก. | G23: 27 | H23: =G23/$E23-1 -> #DIV/0! | I23: 27.75 | J23: =I23/$E23-1 -> #DIV/0! | K23: 28.5 | L23: =K23/$E23-1 -> #DIV/0! | M23: 30.25 | N23: =M23/$E23-1 -> #DIV/0!
B24: 0.72 | C24: C&T ซีลายน์ 7.1-7.3 กก. | G24: 29.25 | H24: =G24/$E24-1 -> #DIV/0! | I24: 30.25 | J24: =I24/$E24-1 -> #DIV/0! | K24: 31.25 | L24: =K24/$E24-1 -> #DIV/0! | M24: 33 | N24: =M24/$E24-1 -> #DIV/0!
B25: 0.78 | C25: C&T ซีลายน์ 7.7-7.9 กก. | G25: 31.75 | H25: =G25/$E25-1 -> #DIV/0! | I25: 33 | J25: =I25/$E25-1 -> #DIV/0! | K25: 33.75 | L25: =K25/$E25-1 -> #DIV/0! | M25: 35.75 | N25: =M25/$E25-1 -> #DIV/0!
B26: 0.81 | C26: C&T ซีลายน์ 8.0-8.2 กก. | G26: 33 | H26: =G26/$E26-1 -> #DIV/0! | I26: 34.25 | J26: =I26/$E26-1 -> #DIV/0! | K26: 35 | L26: =K26/$E26-1 -> #DIV/0! | M26: 37 | N26: =M26/$E26-1 -> #DIV/0!
B27: 0.925 | C27: C&T ซีลายน์ 9.0-9.5 กก. | G27: 37.75 | H27: =G27/$E27-1 -> #DIV/0! | I27: 39 | J27: =I27/$E27-1 -> #DIV/0! | K27: 40 | L27: =K27/$E27-1 -> #DIV/0! | M27: 42.25 | N27: =M27/$E27-1 -> #DIV/0!
C29: 2. ฉากสังกะสี
A30: =_xlfn.XLOOKUP(Sheet1!B30,Sheet2!$A$2:$A$9,Sheet2!$B$2:$B$9) -> 3 | B30: อมรชัย | C30: ฉากสังกะสี 6 หุน No.30 (บาง) 3.0kg-3.5kg | G30: 7.25 | H30: =G30/$E30-1 -> #DIV/0! | I30: 7.5 | J30: =I30/$E30-1 -> #DIV/0! | K30: 7.75 | L30: =K30/$E30-1 -> #DIV/0! | M30: 8 | N30: =M30/$E30-1 -> #DIV/0!
A31: =_xlfn.XLOOKUP(Sheet1!B31,Sheet2!$A$2:$A$9,Sheet2!$B$2:$B$9) -> 3 | B31: อมรชัย | C31: ฉากสังกะสี 6 หุน No.30 (บาง) 4.0kg-4.5kg | G31: 9.5 | H31: =G31/$E31-1 -> #DIV/0! | I31: 9.75 | J31: =I31/$E31-1 -> #DIV/0! | K31: 10 | L31: =K31/$E31-1 -> #DIV/0! | M31: 10.25 | N31: =M31/$E31-1 -> #DIV/0!
A32: =_xlfn.XLOOKUP(Sheet1!B32,Sheet2!$A$2:$A$9,Sheet2!$B$2:$B$9) -> 3 | B32: อมรชัย | C32: ฉากสังกะสี 1"x 1" No.26 (6.0-6.5 kg) | G32: 12 | H32: =G32/$E32-1 -> #DIV/0! | I32: 12.25 | J32: =I32/$E32-1 -> #DIV/0! | K32: 12.5 | L32: =K32/$E32-1 -> #DIV/0! | M32: 12.75 | N32: =M32/$E32-1 -> #DIV/0!
A33: =_xlfn.XLOOKUP(Sheet1!B33,Sheet2!$A$2:$A$9,Sheet2!$B$2:$B$9) -> 1 | B33: ทีรกร | C33: ฉากสังกะสี 6 หุน No.30 (หนา) 4.0kg-4.5 kg | G33: 6.75 | H33: =G33/$E33-1 -> #DIV/0! | I33: 7 | J33: =I33/$E33-1 -> #DIV/0! | K33: 7.25 | L33: =K33/$E33-1 -> #DIV/0! | M33: 7.5 | N33: =M33/$E33-1 -> #DIV/0!
A34: =_xlfn.XLOOKUP(Sheet1!B34,Sheet2!$A$2:$A$9,Sheet2!$B$2:$B$9) -> 1 | B34: ทีรกร | C34: ฉากสังกะสี 6 หุน No.30 (หนา) 5.0kg-5.5 kg | G34: 7.75 | H34: =G34/$E34-1 -> #DIV/0! | I34: 8 | J34: =I34/$E34-1 -> #DIV/0! | K34: 8.25 | L34: =K34/$E34-1 -> #DIV/0! | M34: 8.5 | N34: =M34/$E34-1 -> #DIV/0!
A35: =_xlfn.XLOOKUP(Sheet1!B35,Sheet2!$A$2:$A$9,Sheet2!$B$2:$B$9) -> 2 | B35: C&T | C35: ฉากสังกะสี 6 หุน No.30 (หนา) 5.0kg-5.5 kg | G35: 6.75 | H35: =G35/$E35-1 -> #DIV/0! | I35: 7 | J35: =I35/$E35-1 -> #DIV/0! | K35: 7.25 | L35: =K35/$E35-1 -> #DIV/0! | M35: 7.5 | N35: =M35/$E35-1 -> #DIV/0!
A36: =_xlfn.XLOOKUP(Sheet1!B36,Sheet2!$A$2:$A$9,Sheet2!$B$2:$B$9) -> 2 | B36: C&T | C36: ฉากสังกะสี 6 หุน No.30 (บาง) 3.0kg-3.5 kg | G36: 5.75 | H36: =G36/$E36-1 -> #DIV/0! | I36: 6 | J36: =I36/$E36-1 -> #DIV/0! | K36: 6.25 | L36: =K36/$E36-1 -> #DIV/0! | M36: 6.5 | N36: =M36/$E36-1 -> #DIV/0!
A37: =_xlfn.XLOOKUP(Sheet1!B37,Sheet2!$A$2:$A$9,Sheet2!$B$2:$B$9) -> 2 | B37: C&T | C37: ฉากสังกะสี 1"x 1" No.26 (6.0-8.0 kg) | G37: 9 | H37: =G37/$E37-1 -> #DIV/0! | I37: 9.25 | J37: =I37/$E37-1 -> #DIV/0! | K37: 9.5 | L37: =K37/$E37-1 -> #DIV/0! | M37: 9.75 | N37: =M37/$E37-1 -> #DIV/0!
A38: =_xlfn.XLOOKUP(Sheet1!B38,Sheet2!$A$2:$A$9,Sheet2!$B$2:$B$9) -> 1 | B38: ทีรกร | C38: ฉากสังกะสี 1"x 1" No.26 (6.0-6.5 kg) | G38: 10 | H38: =G38/$E38-1 -> #DIV/0! | I38: 10.25 | J38: =I38/$E38-1 -> #DIV/0! | K38: 10.5 | L38: =K38/$E38-1 -> #DIV/0! | M38: 10.75 | N38: =M38/$E38-1 -> #DIV/0!
A41: 1,2 | C41: 3. โครงผนัง (ซี ยู) โรงงาน ทีรกร / C&T
C42: โครงผนังตัว C 6.5 x 240 cm. No.24 | G42: 48 | H42: =G42/$E42-1 -> #DIV/0! | I42: 50 | J42: =I42/$E42-1 -> #DIV/0! | K42: 51.5 | L42: =K42/$E42-1 -> #DIV/0! | M42: 52.5 | N42: =M42/$E42-1 -> #DIV/0!
C43: โครงผนังตัว C 6.5 x 300 cm. No.24 | G43: 59.5 | H43: =G43/$E43-1 -> #DIV/0! | I43: 61.75 | J43: =I43/$E43-1 -> #DIV/0! | K43: 63.5 | L43: =K43/$E43-1 -> #DIV/0! | M43: 65 | N43: =M43/$E43-1 -> #DIV/0!
C44: โครงผนังตัว C 7.5 x 240 cm. No.24 | G44: 51 | H44: =G44/$E44-1 -> #DIV/0! | I44: 53 | J44: =I44/$E44-1 -> #DIV/0! | K44: 54.5 | L44: =K44/$E44-1 -> #DIV/0! | M44: 55.25 | N44: =M44/$E44-1 -> #DIV/0!
C45: โครงผนังตัว C 7.5 x 300 cm. No.24 | G45: 62.5 | H45: =G45/$E45-1 -> #DIV/0! | I45: 65.5 | J45: =I45/$E45-1 -> #DIV/0! | K45: 67 | L45: =K45/$E45-1 -> #DIV/0! | M45: 68.5 | N45: =M45/$E45-1 -> #DIV/0!
C46: โครงผนังตัว C 6.5 x 240 cm. No.26 | G46: 36.25 | H46: =G46/$E46-1 -> #DIV/0! | I46: 37.75 | J46: =I46/$E46-1 -> #DIV/0! | K46: 38.75 | L46: =K46/$E46-1 -> #DIV/0! | M46: 39.5 | N46: =M46/$E46-1 -> #DIV/0!
...

Sheet Sheet2
A1: ชื่อผู้ขาย | B1: หมายเลข
A2: ทีรกร | B2: 1
A3: C&T | B3: 2
A4: อมรชัย | B4: 3
A5: ประวิทย์ | B5: 4
A6: โพลีแมท | B6: 5
A7: สยาม | B7: 6
A8: เจมยี | B8: 7
A9: ตระกูลไทย | B9: 8

Sheet Ref.
A1: ซีลายน์ 5.0-5.5 กก. | B1: ซีลายน์ 5.6-5.9 กก. | C1: ซีลายน์ 6.0-6.5 กก. | D1: ซีลายน์ 6.6-6.9 กก. | E1: ซีลายน์ 7.0-7.5 กก. | F1: ทีรกร ซีลายน์ 5.0-5.5 กก. | G1: ทีรกร ซีลายน์ 5.6-5.9 กก. | H1: ทีรกร ซีลายน์ 6.0-6.5 กก. | I1: ทีรกร ซีลายน์ 6.6-6.9 กก. | J1: ทีรกร ซีลายน์ 7.0-7.5 กก. | K1: ทีรกร ซีลายน์ 7.6-7.9 กก. | L1: ทีรกร ซีลายน์ 8.0-8.5 กก. | M1: ทีรกร ซีลายน์ 9.0-9.5 กก. | N1: ทีรกร ซีลายน์ 10.0-10.5 กก. | O1: C&T ซีลายน์ 5.3-5.5 กก. | P1: C&T ซีลายน์ 5.6-5.8 กก. | Q1: C&T ซีลายน์ 6.2-6.4 กก. | R1: C&T ซีลายน์ 6.5-6.7 กก. | S1: C&T ซีลายน์ 7.1-7.3 กก. | T1: C&T ซีลายน์ 7.7-7.9 กก. | U1: C&T ซีลายน์ 8.0-8.2 กก. | V1: C&T ซีลายน์ 9.0-9.5 กก. | W1: ฉากสังกะสี 6 หุน No.30 (บาง) 3.0kg-3.5kg | X1: ฉากสังกะสี 6 หุน No.30 (บาง) 4.0kg-4.5kg | Y1: ฉากสังกะสี 1"x 1" No.26 (6.0-6.5 kg) | Z1: ฉากสังกะสี 6 หุน No.30 (หนา) 4.0kg-4.5 kg | AA1: ฉากสังกะสี 6 หุน No.30 (หนา) 5.0kg-5.5 kg | AB1: ฉากสังกะสี 6 หุน No.30 (หนา) 5.0kg-5.5 kg | AC1: ฉากสังกะสี 6 หุน No.30 (บาง) 3.0kg-3.5 kg | AD1: ฉากสังกะสี 1"x 1" No.26 (6.0-8.0 kg) | AE1: ฉากสังกะสี 1"x 1" No.26 (6.0-6.5 kg) | AF1: โครงผนังตัว C 6.5 x 240 cm. No.24 | AG1: โครงผนังตัว C 6.5 x 300 cm. No.24 | AH1: โครงผนังตัว C 7.5 x 240 cm. No.24 | AI1: โครงผนังตัว C 7.5 x 300 cm. No.24 | AJ1: โครงผนังตัว C 6.5 x 240 cm. No.26 | AK1: โครงผนังตัว C 6.5 x 300 cm. No.26 | AL1: โครงผนังตัว C 7.5 x 240 cm. No.26 | AM1: โครงผนังตัว C 7.5 x 300 cm. No.26 | AN1: โครงผนังตัว U 6.5 x 240 cm. No.24 | AO1: โครงผนังตัว U 6.5 x 300 cm. No.24 | AP1: โครงผนังตัว U 7.5 x 240 cm. No.24 | AQ1: โครงผนังตัว U 7.5 x 300 cm. No.24 | AR1: โครงผนังตัว U 6.5 x 240 cm. No.26 | AS1: โครงผนังตัว U 6.5 x 300 cm. No.26 | AT1: โครงผนังตัว U 7.5 x 240 cm. No.26 | AU1: โครงผนังตัว U 7.5 x 300 cm. No.26 | AV1: ซอยผนัง 6.5 x 60 cm. No.24 | AW1: ซอยผนัง 7.5 x 60 cm. No.24 | AX1: ซอยผนัง 6.5 x 60 cm. No.26 | AY1: ซอยผนัง 7.5 x 60 cm. No.26 | AZ1: โครงผนังตัว C 6.5 x 240 cm. No.24 | BA1: โครงผนังตัว C 6.5 x 300 cm. No.24 | BB1: โครงผนังตัว C 7.5 x 240 cm. No.24 | BC1: โครงผนังตัว C 7.5 x 300 cm. No.24 | BD1: โครงผนังตัว C 6.5 x 240 cm. No.26 | BE1: โครงผนังตัว C 6.5 x 300 cm. No.26 | BF1: โครงผนังตัว C 7.5 x 240 cm. No.26 | BG1: โครงผนังตัว C 7.5 x 300 cm. No.26 | BH1: โครงผนังตัว U 6.5 x 240 cm. No.24 | BI1: โครงผนังตัว U 6.5 x 300 cm. No.24 | BJ1: โครงผนังตัว U 7.5 x 240 cm. No.24 | BK1: โครงผนังตัว U 7.5 x 300 cm. No.24 | BL1: โครงผนังตัว U 6.5 x 240 cm. No.26 | BM1: โครงผนังตัว U 6.5 x 300 cm. No.26 | BN1: โครงผนังตัว U 7.5 x 240 cm. No.26 | BO1: โครงผนังตัว U 7.5 x 300 cm. No.26 | BP1: ซอยผนัง 6.5 x 60 cm. No.26 | BQ1: ซอยผนัง 7.5 x 60 cm. No.26 | BR1: โครงทีซอย 60 cm. สีอบขาว บาง | BS1: โครงทีซอย 60 cm. สีอบขาว บาง | BT1: โครงทีซอย 60 ซม. สีขาว บาง | BU1: โครงทีซอย 60 ซม. สีขาว กลาง | BV1: โครงทีซอย 60 ซม. สีขาว หนา | BW1: โครงทีเมน 1"x1" สีอบขาว บาง | BX1: โครงทีเมน 1"x1" สีอบขาว บาง | BY1: โครงทีเมน 1" x 1" สีขาว บาง | BZ1: โครงทีเมน 1"x1" สีขาว กลาง | CA1: โครงทีเมน 1" x 1" สีขาว หนา | CB1: โครงริม 6 หุน สีอบขาว (ฉากระดับเคลือบสี) | CC1: โครงริม 6 หุน สีอบขาว (ฉากระดับเคลือบสี) | CD1: แปสังกะสี 0.50 - 0.54 กก | CE1: แปสังกะสี 0.55 - 0.59 กก | CF1: แปสังกะสี 0.60 - 0.64 กก | CG1: แปสังกะสี 0.65 - 0.69 กก (ซิงค์สีเทา) | CH1: แปสังกะสี 0.70 - 0.75 กก (ซิงค์สีเทา) | CI1: แปสังกะสี 0.50 - 0.54 กก | CJ1: แปสังกะสี 0.55 - 0.59 กก | CK1: แปสังกะสี 0.60 - 0.64 กก | CL1: ล็อคกิ้งคีย์ (บาง) (ทีรกร) | CM1: ล็อคกิ้งคีย์ (หนา) (ทีรกร) | CN1: ล็อคกิ้งคีย์ (C&T) | CO1: ล็อคกิ้งคีย์ บาง (อมรชัย) ** 2,000 ตัว / ลัง** | CP1: ล็อคกิ้งคีย์ หนา (อมรชัย) ** 2,000 ตัว / ลัง** | CQ1: ล็อคกิ้งคีย์ B (บาง) (ประวิทย์) | CR1: ล็อคกิ้งคีย์ A (หนา) (ประวิทย์) | CS1: ตะขอแขวน (ทีรกร) | CT1: ตะขอแขวน (C&T) | CU1: ตะขอแขวน (อมรชัย) ** 2,000 ตัว/กระสอบ ** | CV1: ตะขอแขวน (ประวิทย์) | CW1: สปริงดำ (ทีรกร) | CX1: สปริงดำ (อมรชัย) | CY1: สปริงดำ (C&T) | CZ1: สปริงดำ (ประวิทย์) | DA1: ลวดซีลาย 3.1 ม (ทีรกร) | DB1: ลวดซีลาย 4.0 ม (ทีรกร) | DC1: ลวดซีลาย 3.1 ม (C&T) | DD1: ลวดซีลาย 4.0 ม (C&T) | DE1: ลวดซีลาย 3.1 ม (อมรชัย) แบบชุบ | DF1: ลวดซีลาย (หนา 4.0 มม.) | DG1: ฉาก 2 รู (ทีรกร) | DH1: ฉาก 2 รู (C&T) | DI1: ฉาก 2 รู (อมรชัย) ** 3,000 ตัว/ลัง ** | DJ1: พุกเหล็ก 1.5หุน (100 ตัว/ถุง) | DK1: พุกเหล็ก 2หุน (100 ตัว/ถุง) | DL1: พุกเหล็ก 1.5หุน (100 ตัว/ถุง) | DM1: ผ้าฉาบ (3 ม้วน/ห่อ) | DN1: ผ้าฉาบ (3 ม้วน/ห่อ) ** 50 ห่อ/ลัง ** | DO1: ผ้าฉาบ (3 ม้วน/ห่อ) | DP1: ผ้าฉาบ ไฟเบอร์กลาส 3 ซม. x 20 ม. (72ม้วน/ลัง) | DQ1: ผ้าฉาบ ไฟเบอร์กลาส 5 ซม. x 20 ม. (72 ม้วน/ลัง) | DR1: ผ้าฉาบ ไฟเบอร์กลาส 5 ซม. x 45 ม. (54 ม้วน/ลัง) | DS1: สกรูยิปซั่ม 6 หุน (19 มม. - ญ) 7 ขีด | DT1: สกรูยิปซั่ม 6 หุน (19 มม. - ญ) 6 ขีด | DU1: สกรูยิปซั่ม 6 หุน (19 มม.- ล) 5 ขีด | DV1: สกรูยิปซั่ม 6 หุน (19 มม.- ล) 5 ขีด | DW1: สกรูยิปซั่ม 1 นิ้ว (25.4 มม.- ญ) 7 ขีด | DX1: สกรูยิปซั่ม 1 นิ้ว (25.4 มม.- ญ) 6 ขีด | DY1: สกรูยิปซั่ม 1 นิ้ว (25.4 มม.- ล) 5 ขีด | DZ1: สกรูยิปซั่ม 1 นิ้ว (25.4 มม.- ล) 5 ขีด | EA1: สกรูยิปซั่ม 1 1/2 นิ้ว (38.1 มม.) 7 ขีด | EB1: สกรูยิปซั่ม 1 1/2 นิ้ว (38.1 มม.) 6 ขีด | EC1: สกรูยิปซั่ม 1 1/2 นิ้ว (38.1 มม.) 5 ขีด | ED1: สกรูยิปซั่ม 2 นิ้ว (50.8 มม.) 7 ขีด | EE1: สกรูยิปซั่ม 2 นิ้ว (50.8 มม.) 6 ขีด | EF1: สกรูยิปซั่ม 2 นิ้ว (50.8 มม.) 5 ขีด | EG1: สกรูยิงสมาร์ทบอร์ด 6X1 | EH1: สกรูยิงสมาร์ทบอร์ด 6 X 3/4 | EI1: สกรูยิงโครงคร่าว 3 หุน (10 มม.) No.6 | EJ1: กระดาษทราย No.3 | EK1: กระดาษทราย No.4 | EL1: ลวดเบอร์ 18 | EM1: ลวดเบอร์ 18 | EN1: ตะปูตีฉาก (1 Kg.) | EO1: ตะปูตีฉาก (0.5 Kg.) | EP1: สีอะครีลิค TG 5.0 แกลลอน สีควันบุหรี่ | EQ1: แปรงทาสีด้ามไม้ PUMKIN 1" | ER1: แปรงทาสีด้ามไม้ PUMKIN 2" | ES1: แปรงทาสีด้ามไม้ PUMKIN 4" | ET1: แปรงลูกกลิ้งทาสี 10 นิ้ว รุ่นมืออาชีพ PUMPKIN-PRO
