Workbook

Sheet Formular 4 step Y1
D1: 46113
D2: BKK | E2: CM | F2: CR | G2: PL | H2: NS | I2: KK | J2: SK | K2: UD | L2: UB | M2: NR | N2: RB | O2: PC | P2: BS | Q2: AY | R2: RY | S2: CB | T2: SR | U2: PK | V2: HY | W2: SB
A3: Y01010100109120240 | B3: STD 9 mm. | C3: Price List | D3: 238 | E3: 238 | F3: 238 | G3: 238 | H3: 238 | I3: 238 | J3: 238 | K3: 238 | L3: 238 | M3: 238 | N3: 238 | O3: 238 | P3: 238 | Q3: 238 | R3: 238 | S3: 238 | T3: 238 | U3: 238 | V3: 238 | W3: 238
A4: Y01010200109120240 | B4: Discount | D4: 0.03 | E4: 0.025 | F4: 0.025 | G4: 0.025 | H4: 0.025 | I4: 0.03 | J4: 0.03 | K4: 0.03 | L4: 0.03 | M4: 0.03 | N4: 0.04 | O4: 0.04 | P4: 0.04 | Q4: 0.04 | R4: 0.04 | S4: 0.04 | T4: 0.04 | U4: 0.04 | V4: 0.04 | W4: 0.04
D5: =D3*(1-D4) -> 230.86 | E5: =E3*(1-E4) -> 232.05 | F5: =F3*(1-F4) -> 232.05 | G5: =G3*(1-G4) -> 232.05 | H5: =H3*(1-H4) -> 232.05 | I5: =I3*(1-I4) -> 230.86 | J5: =J3*(1-J4) -> 230.86 | K5: =K3*(1-K4) -> 230.86 | ... W5: =W3*(1-W4) -> 228.48
B6: Discount | C6: 0 | D6: =D5*$C6 -> 0 | E6: =E5*$C6 -> 0 | F6: =F5*$C6 -> 0 | G6: =G5*$C6 -> 0 | H6: =H5*$C6 -> 0 | I6: =I5*$C6 -> 0 | J6: =J5*$C6 -> 0 | K6: =K5*$C6 -> 0 | ... W6: =W5*$C6 -> 0
B7: RE (ex VAT) | D7: =D5-D6 -> 230.86 | E7: =E5-E6 -> 232.05 | F7: =F5-F6 -> 232.05 | G7: =G5-G6 -> 232.05 | H7: =H5-H6 -> 232.05 | I7: =I5-I6 -> 230.86 | J7: =J5-J6 -> 230.86 | K7: =K5-K6 -> 230.86 | ... W7: =W5-W6 -> 228.48
B8: VAT | C8: 0.07 | D8: =D7*$C8 -> 16.1602 | E8: =E7*$C8 -> 16.2435 | F8: =F7*$C8 -> 16.2435 | G8: =G7*$C8 -> 16.2435 | H8: =H7*$C8 -> 16.2435 | I8: =I7*$C8 -> 16.1602 | J8: =J7*$C8 -> 16.1602 | K8: =K7*$C8 -> 16.1602 | ... W8: =W7*$C8 -> 15.9936
B9: Net Price (inc VAT) | D9: =D7+D8 -> 247.0202 | E9: =E7+E8 -> 248.2935 | F9: =F7+F8 -> 248.2935 | G9: =G7+G8 -> 248.2935 | H9: =H7+H8 -> 248.2935 | I9: =I7+I8 -> 247.0202 | J9: =J7+J8 -> 247.0202 | K9: =K7+K8 -> 247.0202 | ... W9: =W7+W8 -> 244.4736
B10: Transportation
B11: COGS | D11: =SUM(D9:D10) -> 247.0202 | E11: =SUM(E9:E10) -> 248.2935 | F11: =SUM(F9:F10) -> 248.2935 | G11: =SUM(G9:G10) -> 248.2935 | H11: =SUM(H9:H10) -> 248.2935 | I11: =SUM(I9:I10) -> 247.0202 | J11: =SUM(J9:J10) -> 247.0202 | K11: =SUM(K9:K10) -> 247.0202 | ... W11: =SUM(W9:W10) -> 244.4736
B12: Promotion Rebate
B13: Net Cost | D13: =D11 -> 247.0202 | E13: =E11 -> 248.2935 | F13: =F11 -> 248.2935 | G13: =G11 -> 248.2935 | H13: =H11 -> 248.2935 | I13: =I11 -> 247.0202 | J13: =J11 -> 247.0202 | K13: =K11 -> 247.0202 | ... W13: =W11 -> 244.4736
B14: Price : W1 | D14: 124 | E14: 136 | F14: 139 | G14: 134 | H14: 129 | I14: 134 | J14: 138 | K14: 136 | L14: 137 | M14: 132 | N14: 124 | O14: 124 | P14: 124 | Q14: 124 | R14: 124 | S14: 124 | T14: 126 | U14: 129 | V14: 120 | W14: 124
B15: Price : W2 | D15: 125 | E15: 137 | F15: 140 | G15: 135 | H15: 130 | I15: 135 | J15: 139 | K15: 137 | L15: 138 | M15: 133 | N15: 125 | O15: 125 | P15: 125 | Q15: 125 | R15: 125 | S15: 125 | T15: 127 | U15: 130 | V15: 121 | W15: 125
B16: Price : R1 | D16: 126 | E16: 138 | F16: 141 | G16: 136 | H16: 131 | I16: 136 | J16: 140 | K16: 138 | L16: 139 | M16: 134 | N16: 126 | O16: 126 | P16: 126 | Q16: 126 | R16: 126 | S16: 126 | T16: 128 | U16: 131 | V16: 122 | W16: 126
B17: Price : R2 | D17: 127 | E17: 139 | F17: 142 | G17: 137 | H17: 132 | I17: 137 | J17: 141 | K17: 139 | L17: 140 | M17: 135 | N17: 127 | O17: 127 | P17: 127 | Q17: 127 | R17: 127 | S17: 127 | T17: 129 | U17: 132 | V17: 123 | W17: 127
B18: MG/Bht : W1 | D18: =+D14-D13 -> -123.0202 | E18: =+E14-E13 -> -112.2935 | F18: =+F14-F13 -> -109.2935 | G18: =+G14-G13 -> -114.2935 | H18: =+H14-H13 -> -119.2935 | I18: =+I14-I13 -> -113.0202 | J18: =+J14-J13 -> -109.0202 | K18: =+K14-K13 -> -111.0202 | ... W18: =+W14-W13 -> -120.4736
B19: MG/Bht : W2 | D19: =+D15-D$13 -> -122.0202 | E19: =+E15-E$13 -> -111.2935 | F19: =+F15-F$13 -> -108.2935 | G19: =+G15-G$13 -> -113.2935 | H19: =+H15-H$13 -> -118.2935 | I19: =+I15-I$13 -> -112.0202 | J19: =+J15-J$13 -> -108.0202 | K19: =+K15-K$13 -> -110.0202 | ... W19: =+W15-W$13 -> -119.4736
B20: MG/Bht : R1 | D20: =+D16-D$13 -> -121.0202 | E20: =+E16-E$13 -> -110.2935 | F20: =+F16-F$13 -> -107.2935 | G20: =+G16-G$13 -> -112.2935 | H20: =+H16-H$13 -> -117.2935 | I20: =+I16-I$13 -> -111.0202 | J20: =+J16-J$13 -> -107.0202 | K20: =+K16-K$13 -> -109.0202 | ... W20: =+W16-W$13 -> -118.4736
B21: MG/Bht : R2 | D21: =+D17-D$13 -> -120.0202 | E21: =+E17-E$13 -> -109.2935 | F21: =+F17-F$13 -> -106.2935 | G21: =+G17-G$13 -> -111.2935 | H21: =+H17-H$13 -> -116.2935 | I21: =+I17-I$13 -> -110.0202 | J21: =+J17-J$13 -> -106.0202 | K21: =+K17-K$13 -> -108.0202 | ... W21: =+W17-W$13 -> -117.4736
B22: MG/% : W1 | D22: =+D18/D14 -> -0.99209839 | E22: =+E18/E14 -> -0.8256875 | F22: =+F18/F14 -> -0.78628417 | G22: =+G18/G14 -> -0.85293657 | H22: =+H18/H14 -> -0.92475581 | I22: =+I18/I14 -> -0.84343433 | J22: =+J18/J14 -> -0.79000145 | K22: =+K18/K14 -> -0.816325 | ... W22: =+W18/W14 -> -0.97156129
B23: MG/% : W2 | D23: =+D19/D15 -> -0.9761616 | E23: =+E19/E15 -> -0.81236131 | F23: =+F19/F15 -> -0.773525 | G23: =+G19/G15 -> -0.83921111 | H23: =+H19/H15 -> -0.90995 | I23: =+I19/I15 -> -0.82977926 | J23: =+J19/J15 -> -0.77712374 | K23: =+K19/K15 -> -0.80306715 | ... W23: =+W19/W15 -> -0.9557888
B24: MG/% : R1 | D24: =+D20/D16 -> -0.96047778 | E24: =+E20/E16 -> -0.79922826 | F24: =+F20/F16 -> -0.76094681 | G24: =+G20/G16 -> -0.8256875 | H24: =+H20/H16 -> -0.89537023 | I24: =+I20/I16 -> -0.816325 | J24: =+J20/J16 -> -0.76443 | K24: =+K20/K16 -> -0.79000145 | ... W24: =+W20/W16 -> -0.94026667
B25: MG/% : R2 | D25: =+D21/D17 -> -0.94504094 | E25: =+E21/E17 -> -0.78628417 | F25: =+F21/F17 -> -0.74854577 | G25: =+G21/G17 -> -0.81236131 | H25: =+H21/H17 -> -0.88101136 | I25: =+I21/I17 -> -0.80306715 | J25: =+J21/J17 -> -0.75191631 | K25: =+K21/K17 -> -0.77712374 | ... W25: =+W21/W17 -> -0.92498898
A27: Y01010700109120240 | B27: SYNIA 9 mm. | D27: BKK | E27: CM | F27: CR | G27: PL | H27: NS | I27: KK | J27: SK | K27: UD | L27: UB | M27: NR | N27: RB | O27: PC | P27: BS | Q27: AY | R27: RY | S27: CB | T27: SR | U27: PK | V27: HY | W27: SB
B28: Price List | D28: 274 | E28: =D28 -> 274 | F28: =D28 -> 274 | G28: =D28 -> 274 | H28: =E28 -> 274 | I28: =D28 -> 274 | J28: =D28 -> 274 | K28: =D28 -> 274 | L28: =D28 -> 274 | M28: =D28 -> 274 | N28: =D28 -> 274 | O28: =D28 -> 274 | P28: =D28 -> 274 | Q28: =D28 -> 274 | R28: =D28 -> 274 | S28: =D28 -> 274 | T28: =D28 -> 274 | U28: =D28 -> 274 | V28: =D28 -> 274 | W28: =H28 -> 274
B29: Discount | D29: 0.04 | E29: 0.04 | F29: 0.04 | G29: 0.04 | H29: 0.04 | I29: 0.04 | J29: 0.04 | K29: 0.04 | L29: 0.04 | M29: 0.04 | N29: 0.04 | O29: 0.04 | P29: 0.04 | Q29: 0.04 | R29: 0.04 | S29: 0.04 | T29: 0.04 | U29: 0.04 | V29: 0.04 | W29: 0.04
D30: =D28*(1-D29) -> 263.04 | E30: =E28*(1-E29) -> 263.04 | F30: =F28*(1-F29) -> 263.04 | G30: =G28*(1-G29) -> 263.04 | H30: =H28*(1-H29) -> 263.04 | I30: =I28*(1-I29) -> 263.04 | J30: =J28*(1-J29) -> 263.04 | K30: =K28*(1-K29) -> 263.04 | ... W30: =W28*(1-W29) -> 263.04
B31: Discount | C31: 0 | D31: =D30*$C31 -> 0 | E31: =E30*$C31 -> 0 | F31: =F30*$C31 -> 0 | G31: =G30*$C31 -> 0 | H31: =H30*$C31 -> 0 | I31: =I30*$C31 -> 0 | J31: =J30*$C31 -> 0 | K31: =K30*$C31 -> 0 | ... W31: =W30*$C31 -> 0
B32: RE (ex VAT) | D32: =D30-D31 -> 263.04 | E32: =E30-E31 -> 263.04 | F32: =F30-F31 -> 263.04 | G32: =G30-G31 -> 263.04 | H32: =H30-H31 -> 263.04 | I32: =I30-I31 -> 263.04 | J32: =J30-J31 -> 263.04 | K32: =K30-K31 -> 263.04 | ... W32: =W30-W31 -> 263.04
B33: VAT | C33: 0.07 | D33: =D32*$C33 -> 18.4128 | E33: =E32*$C33 -> 18.4128 | F33: =F32*$C33 -> 18.4128 | G33: =G32*$C33 -> 18.4128 | H33: =H32*$C33 -> 18.4128 | I33: =I32*$C33 -> 18.4128 | J33: =J32*$C33 -> 18.4128 | K33: =K32*$C33 -> 18.4128 | ... W33: =W32*$C33 -> 18.4128
B34: Net Price (inc VAT) | D34: =D32+D33 -> 281.4528 | E34: =E32+E33 -> 281.4528 | F34: =F32+F33 -> 281.4528 | G34: =G32+G33 -> 281.4528 | H34: =H32+H33 -> 281.4528 | I34: =I32+I33 -> 281.4528 | J34: =J32+J33 -> 281.4528 | K34: =K32+K33 -> 281.4528 | ... W34: =W32+W33 -> 281.4528
B35: Transportation
B36: COGS | D36: =SUM(D34:D35) -> 281.4528 | E36: =SUM(E34:E35) -> 281.4528 | F36: =SUM(F34:F35) -> 281.4528 | G36: =SUM(G34:G35) -> 281.4528 | H36: =SUM(H34:H35) -> 281.4528 | I36: =SUM(I34:I35) -> 281.4528 | J36: =SUM(J34:J35) -> 281.4528 | K36: =SUM(K34:K35) -> 281.4528 | ... W36: =SUM(W34:W35) -> 281.4528
B37: Promotion Rebate
B38: Net Cost | D38: =D36 -> 281.4528 | E38: =E36 -> 281.4528 | F38: =F36 -> 281.4528 | G38: =G36 -> 281.4528 | H38: =H36 -> 281.4528 | I38: =I36 -> 281.4528 | J38: =J36 -> 281.4528 | K38: =K36 -> 281.4528 | ... W38: =W36 -> 281.4528
B39: Price : W1 | D39: 124 | E39: 139 | F39: 141 | G39: 136 | H39: 132 | I39: 133 | J39: 137 | K39: 135 | L39: 137 | M39: 131 | N39: 124 | O39: 124 | P39: 124 | Q39: 124 | R39: 124 | S39: 124 | T39: 128 | U39: 131 | V39: 123 | W39: 124
B40: Price : W2 | D40: 125 | E40: 140 | F40: 142 | G40: 137 | H40: 133 | I40: 134 | J40: 138 | K40: 136 | L40: 138 | M40: 132 | N40: 125 | O40: 125 | P40: 125 | Q40: 125 | R40: 125 | S40: 125 | T40: 129 | U40: 132 | V40: 124 | W40: 125
B41: Price : R1 | D41: 126 | E41: 141 | F41: 143 | G41: 138 | H41: 134 | I41: 135 | J41: 139 | K41: 137 | L41: 139 | M41: 133 | N41: 126 | O41: 126 | P41: 126 | Q41: 126 | R41: 126 | S41: 126 | T41: 130 | U41: 133 | V41: 125 | W41: 126
...

Sheet Sheet1
A1: STD 9 mm. | B1: SYNIA 9 mm. | C1: TEC 9 mm. | D1: SYNIA TEC 9 mm. | E1: STD 12 mm. | F1: TEC 12 mm. | G1: ทนไฟ 12 มม. | H1: ทนไฟ 15 มม. | I1: ยิปซัมลดเสียงสะท้อน เอคโค่บล็อค | J1: Paper touch ลวดลาย | K1: Paper touch หยาดเพชร | L1: Paper touch หยาดเพชร ติดฟอยลด์ | M1: Color touch 60x60 9 mm. | N1: Color touch 60x120 9 mm. | O1: Color touch 60x60 9 mm.ทนชื้น | P1: Color touch 60x120 ทนชื้น 9 มม. | Q1: เซิฟบอร์ด ขนาด 30 ซม. | R1: เซิฟบอร์ด ขนาด 45 ซม. | S1: เซิฟบอร์ด ขนาด 60 ซม. | T1: เซิฟบอร์ด ขนาด 60*120 ซม. | U1: เซิฟบอร์ด ขนาด 30 ซม. ทนชื้น | V1: เซิฟบอร์ด ขนาด 45 ซม. ทนชื้น | W1: เซิฟบอร์ด ขนาด 60 ซม. ทนชื้น | X1: เซิฟบอร์ด ขนาด 60*120 ซม. ทนชื้น | Y1: อะคูสติก กาแลคซี่ | Z1: อะคูสติก-อิมเพรสชันME903 | AA1: อะคูสติก-อิมเพรสชันME904 | AB1: อะคูสติก-อิมเพรสชันME905 | AC1: อะคูสติก-อิมเพรสชันME908 | AD1: คนอฟ | AE1: คนอฟ ทนชื้น/ฟอล์ย | AF1: เวเทอร์บล็อค W0 | AG1: เวเทอร์บล็อค W1 | AH1: STD 15 mm. | AI1: ยิปซัมเฟล็กบอร์ด(ดัดโค้ง) 6 มม. 120*240 มม. | AJ1: Color touch สีมุก/สีเพชร 60x120*12 mm. | AK1: Color touch สีมุก/สีเพชร 60x120*12 mm. ทนชื้น | AL1: SB 120x240 4 mm | AM1: SB 120x120 4 mm | AN1: SB 60x240 4 mm | AO1: SB 120x240 6 mm | AP1: SB 120x240 8 mm | AQ1: SB 120x240 10 mm | AR1: SB 120x240 12 mm | AS1: SB 120x280 8 mm | AT1: ลายไม้/เซาะร่อง | AU1: ระบายอากาศ | AV1: ลายไม้ระบายอากาศ | AW1: ลายไม้ระบายอากาศ โพรเทคชั่น | AX1: SB 60*120 4 mm | AY1: ไม้มอบ | AZ1: ไม้ระแนงลบมุม 7.5 | BA1: Sun 120x240 4 mm | BB1: Sun 120x120 4 mm | BC1: Sun 60x240 4 mm | BD1: Sun 120x240 6 mm | BE1: Sun ไม้มอบ | BF1: Sun ไม้ระแนงลบมุม 7.5 | BG1: Sun 120x240 8 mm | BH1: ระบายอากาศ โพรเทคชั่น 60*120 ซม. 4 มม. | BI1: SB 120x240 15 mm (65.3 Kg.) | BJ1: SB 120x240 16 mm | BK1: SB 120x240 18 mm | BL1: SB 120x240 20 mm (87 Kg.) | BM1: ไม้ฝา ซูเปอร์ซัน 15*300*0.8 สีซิเมนต์ | BN1: SB เซาะร่อง 4" 120*280 8 มม. | BO1: ซีเมนต์บอร์ด 120*240 8 มม. | BP1: ซีเมนต์บอร์ด 120*240 10 มม. | BQ1: ซีเมนต์บอร์ด 120*240 12 มม. | BR1: ซีเมนต์บอร์ด 120*240 16 มม. | BS1: ซีเมนต์บอร์ด 120*240 20 มม. | BT1: ซีเมนต์บอร์ด 120*240 24 มม. | BU1: ไม้ฝา ซูเปอร์ซัน 15*400*0.8 สีซิเมนต์ | BV1: ไม้ฝา ซูเปอร์ซัน 20*300*0.8 สีซิเมนต์ | BW1: ไม้ฝา ซูเปอร์ซัน 20*400*0.8 สีซิเมนต์ | BX1: ไม้พื้น ซูเปอร์ซัน ลายไม้ 10*300*2.5 รองพื้น | BY1: ไม้พื้น ซูเปอร์ซัน ลายไม้ 15*300*2.5 รองพื้น | BZ1: ไม้พื้น ซูเปอร์ซัน ลายไม้ 20*300*2.5 รองพื้น | CA1: ไม้ระแนงลบมุม 10 | CB1: เซาะร่อง ลายเสี้ยน 120*240*6 มม. | CC1: Sun 120x240 15 mm | CD1: Sun 120x240 20 mm | CE1: Rockchill | CF1: Safe 'n' Silent Pro 330 หนา 50 มม. 60*120 | CG1: Safe 'n' Silent Pro 330 หนา 75 มม. 60*120 | CH1: Safe 'n' Silent Pro 350 หนา 50 มม. 60*120 | CI1: Safe 'n' Silent Pro 330 หนา 50 มม. 40*120 | CJ1: Safe 'n' Silent Pro 330 หนา 50 มม. 40*120
A2: Y01010100109120240 | B2: Y01010700109120240 | C2: Y01020000109120240 | D2: Y01020800109120240 | E2: Y01010100112120240 | F2: Y01020300112120240 | G2: Y01021500112120240 | H2: Y01021500115120240 | I2: Y01041400212120240 | J2: Y01062001908060060 | K2: Y01062001708060060 | L2: Y01062001808060060 | M2: Y01062201409060060 | N2: Y01062201409060120 | O2: Y01062301409060060 | P2: Y01062301409060120 | Q2: Y01083300109030030 | R2: Y01083300109045045 | S2: Y01083300109060060 | T2: Y01083300109060120 | U2: Y01083400109030030 | V2: Y01083400109045045 | W2: Y01083400109060060 | X2: Y01083400109060120 | Y2: Y01070104114060120 | Z2: Y01070103516060060 | AA2: Y01070103616060120 | AB2: Y01073203716060060 | AC2: Y01073203816060120 | AD2: Y02010200109120240 | AE2: Y02020400109120240 | AF2: Y01030500909120240 | AG2: Y01031001009120240 | AH2: Y01010200115120240 | AI2: Y01021700106120240 | AJ2: Y01062201412060120 | AK2: Y01062301412060120 | AL2: Y03094001604120240 | AM2: Y03094001604120120 | AN2: Y03094001604060240 | AO2: Y03094001606120240 | AP2: Y03094001608120240 | AQ2: Y03094001610120240 | AR2: Y03094001612120240 | AS2: Y03094101608120280 | AT2: Y03094204804060120 | AU2: Y03094304504060120 | AV2: Y03094304904060120 | AW2: Y03094305004060120 | AX2: Y03094001604060120 | AY2: Y03104501608050300 | AZ2: Y03104601608075301 | BA2: Y04094001604120240 | BB2: Y04094001604120120 | BC2: Y04094001604060240 | BD2: Y04094001606120240 | BE2: Y04104501608050300 | BF2: Y04104601608075300 | BG2: Y04094001608120240 | BH2: Y03094304604060120 | BI2: Y03094001615120240 | BJ2: Y03094001616120240 | BK2: Y03094001618120240 | BL2: Y03094001620120240 | BM2: Y04104701608015300 | BO2: Y03110101608120240 | BP2: Y03110101610120240 | BQ2: Y03110101612120240 | BR2: Y03110101616120240 | BS2: Y03110101620120240 | BT2: Y03110101624120240 | BU2: Y04104701608015400 | BV2: Y04104701608020300 | CA2: Y03104601610100300 | CB2: Y03094007906120240 | CC2: Y04094001615120240 | CD2: Y04094001620120240 | CE2: Y06135105682060400 | CF2: Y06135005881060120 | CG2: Y06135005882060120 | CH2: Y06135005981060120 | CI2: Y06135005981060120 | CJ2: Y06135005881040120
A3: Y01010200109120240 | C3: Y01020300109120240 | D3: Y01020900109120240 | E3: Y01010200012120240 | F3: Y01020400012120240 | I3: Y01041400312120240 | J3: Y01062002008060060 | K3: Y01062101708060060 | L3: Y01062101808060060 | AE3: Y02020600109120240 | AT3: Y03094205104060120
C4: Y01020400109120240 | F4: Y01020400112120240 | I4: Y01041400412120240 | J4: Y01062002108060060
C5: Y01020500109120240 | F5: Y01020600012120240 | I5: Y01041400512120240 | J5: Y01062002208060060
C6: Y01020600109120240 | F6: Y01020600112120240 | J6: Y01062002308060060
J7: Y01062002408060060
J8: Y01062002508060060
J9: Y01062007508060060
J10: Y01062007608060060
J11: Y01062007708060060
J12: Y01062101908060060
J13: Y01062102008060060
J14: Y01062102108060060
J15: Y01062102208060060
J16: Y01062102308060060
J17: Y01062102408060060
J18: Y01062102508060060

Sheet สูตร 4 step SB
A1: Y03094001604120240 | B1: SB 120x240 4 mm | D1: BKK | E1: CM | F1: CR | G1: PL | H1: NS | I1: KK | J1: SK | K1: UD | L1: UB | M1: NR | N1: RB | O1: PC | P1: BS | Q1: AY | R1: RY | S1: CB | T1: SR | U1: PK | V1: HY | W1: SB | Y1: BKK | Z1: CM | AA1: CR | AB1: PL | AC1: NS | AD1: KK | AE1: SK | AF1: UD | AG1: UB | AH1: NR | AI1: RB | AJ1: PC | AK1: BS | AL1: AY | AM1: RY | AN1: CB | AO1: SR | AP1: PK | AQ1: HY | AR1: SB
B2: Price List | D2: 175 | E2: =D2 -> 175 | F2: =D2 -> 175 | G2: =D2 -> 175 | H2: =E2 -> 175 | I2: =D2 -> 175 | J2: =D2 -> 175 | K2: =D2 -> 175 | L2: =D2 -> 175 | M2: =D2 -> 175 | N2: =D2 -> 175 | O2: =D2 -> 175 | P2: =D2 -> 175 | Q2: =D2 -> 175 | R2: =D2 -> 175 | S2: =D2 -> 175 | W2: =J2 -> 175
B3: Discount | D3: 0.26 | E3: =D3 -> 0.26 | F3: =D3 -> 0.26 | G3: =D3 -> 0.26 | H3: =D3 -> 0.26 | I3: =D3 -> 0.26 | J3: =D3 -> 0.26 | K3: =D3 -> 0.26 | L3: =D3 -> 0.26 | M3: =D3 -> 0.26 | N3: =D3 -> 0.26 | O3: =D3 -> 0.26 | P3: =D3 -> 0.26 | Q3: =D3 -> 0.26 | R3: =D3 -> 0.26 | S3: =D3 -> 0.26 | W3: =J3 -> 0.26
B4: ค่าคลัง ตันละ 150 | D4: 0 | E4: 0 | F4: 0 | G4: 0 | H4: 0 | I4: 0 | J4: 0 | K4: 0 | L4: 0 | M4: 0 | N4: 0 | O4: 0 | P4: 0 | Q4: 0 | R4: 0 | S4: 0 | W4: 0
B5: RE (ex VAT) | D5: =D2-(D2*D3) -> 129.5 | E5: =E2-(E2*E3) -> 129.5 | F5: =F2-(F2*F3) -> 129.5 | G5: =G2-(G2*G3) -> 129.5 | H5: =H2-(H2*H3) -> 129.5 | I5: =I2-(I2*I3) -> 129.5 | J5: =J2-(J2*J3) -> 129.5 | K5: =K2-(K2*K3) -> 129.5 | ... S5: =S2-(S2*S3) -> 129.5 | T5: 141.71 | U5: 141.71 | V5: 141.71 | W5: =W2-(W2*W3) -> 129.5
B6: VAT | C6: 0.07 | D6: =D5*$C6 -> 9.065 | E6: =E5*$C6 -> 9.065 | F6: =F5*$C6 -> 9.065 | G6: =G5*$C6 -> 9.065 | H6: =H5*$C6 -> 9.065 | I6: =I5*$C6 -> 9.065 | J6: =J5*$C6 -> 9.065 | K6: =K5*$C6 -> 9.065 | ... W6: =W5*$C6 -> 9.065
B7: Net Price (inc VAT) | D7: =D5+D6 -> 138.565 | E7: =E5+E6 -> 138.565 | F7: =F5+F6 -> 138.565 | G7: =G5+G6 -> 138.565 | H7: =H5+H6 -> 138.565 | I7: =I5+I6 -> 138.565 | J7: =J5+J6 -> 138.565 | K7: =K5+K6 -> 138.565 | ... W7: =W5+W6 -> 138.565
B8: Transportation | D8: =Y10 -> 6.9611111 | E8: =Z10 -> 15.812222 | F8: =AA10 -> 18.975 | G8: =AB10 -> 12.65 | H8: =AC10 -> 6.7766667 | I8: =AD10 -> 9.0355556 | J8: =AE10 -> 14.005556 | K8: =AF10 -> 11.475556 | ... W8: =AR10 -> 6.5055556 | Y8: 12530 | Z8: 28462 | AA8: 34155 | AB8: 22770 | AC8: 12198 | AD8: 16264 | AE8: 25210 | AF8: 20656 | AG8: 24396 | AH8: 11710 | AI8: 13012 | AJ8: 30581 | AK8: 11710 | AL8: 11710 | AM8: 15451 | AN8: 14638 | AP8: 30581 | AR8: 11710
B9: COGS | D9: =SUM(D7:D8) -> 145.52611 | E9: =SUM(E7:E8) -> 154.37722 | F9: =SUM(F7:F8) -> 157.54 | G9: =SUM(G7:G8) -> 151.215 | H9: =SUM(H7:H8) -> 145.34167 | I9: =SUM(I7:I8) -> 147.60056 | J9: =SUM(J7:J8) -> 152.57056 | K9: =SUM(K7:K8) -> 150.04056 | ... W9: =SUM(W7:W8) -> 145.07056 | Y9: 1800 | Z9: 1800 | AA9: 1800 | AB9: 1800 | AC9: 1800 | AD9: 1800 | AE9: 1800 | AF9: 1800 | AG9: 1800 | AH9: 1800 | AI9: 1800 | AJ9: 1800 | AK9: 1800 | AL9: 1800 | AM9: 1800 | AN9: 1800 | AP9: 1800 | AR9: 1800
B10: Promotion Rebate | Y10: =Y8/Y9 -> 6.9611111 | Z10: =Z8/Z9 -> 15.812222 | AA10: =AA8/AA9 -> 18.975 | AB10: =AB8/AB9 -> 12.65 | AC10: =AC8/AC9 -> 6.7766667 | AD10: =AD8/AD9 -> 9.0355556 | AE10: =AE8/AE9 -> 14.005556 | AF10: =AF8/AF9 -> 11.475556 | ... AN10: =AN8/AN9 -> 8.1322222 | AP10: =AP8/AP9 -> 16.989444 | AR10: =AR8/AR9 -> 6.5055556
B11: Net Cost | D11: =D9+D10 -> 145.52611 | E11: =E9+E10 -> 154.37722 | F11: =F9+F10 -> 157.54 | G11: =G9+G10 -> 151.215 | H11: =H9+H10 -> 145.34167 | I11: =I9+I10 -> 147.60056 | J11: =J9+J10 -> 152.57056 | K11: =K9+K10 -> 150.04056 | ... W11: =W9+W10 -> 145.07056
B12: Price : SDM | D12: 0 | E12: 0 | F12: 0 | G12: 0 | H12: 0 | I12: 0 | J12: 0 | K12: 0 | L12: 0 | M12: 0 | N12: 0 | O12: 0 | P12: 0 | Q12: 0 | R12: 0 | S12: 0 | T12: 0 | U12: 0 | V12: 0 | W12: 0
B13: Price : W1 | D13: 156 | E13: 165 | F13: 168 | G13: 162 | H13: 156 | I13: 158 | J13: 163 | K13: 161 | L13: 163 | M13: 156 | N13: 156 | O13: 166 | P13: 156 | Q13: 156 | R13: 158 | S13: 157 | T13: 162 | U13: 179 | V13: 162 | W13: 156
B14: Price : W2 | D14: 159 | E14: 168 | F14: 171 | G14: 165 | H14: 159 | I14: 161 | J14: 166 | K14: 164 | L14: 166 | M14: 159 | N14: 159 | O14: 169 | P14: 159 | Q14: 159 | R14: 161 | S14: 160 | T14: 165 | U14: 182 | V14: 165 | W14: 159
B15: Price : R1 | D15: 161 | E15: 170 | F15: 173 | G15: 167 | H15: 161 | I15: 163 | J15: 168 | K15: 166 | L15: 168 | M15: 161 | N15: 161 | O15: 171 | P15: 161 | Q15: 161 | R15: 163 | S15: 162 | T15: 167 | U15: 184 | V15: 167 | W15: 161
B16: Price : R2 | D16: 163 | E16: 172 | F16: 175 | G16: 169 | H16: 163 | I16: 165 | J16: 170 | K16: 168 | L16: 170 | M16: 163 | N16: 163 | O16: 173 | P16: 163 | Q16: 163 | R16: 165 | S16: 164 | T16: 169 | U16: 186 | V16: 169 | W16: 163
B17: MG/Bht : SDM | D17: 0 | E17: 0 | F17: 0 | G17: 0 | H17: 0 | I17: 0 | J17: 0 | K17: 0 | L17: 0 | M17: 0 | N17: 0 | O17: 0 | P17: 0 | Q17: 0 | R17: 0 | S17: 0 | T17: 0 | U17: 0 | V17: 0 | W17: 0
B18: MG/Bht : W1 | D18: =+D13-D$11 -> 10.473889 | E18: =+E13-E$11 -> 10.622778 | F18: =+F13-F$11 -> 10.46 | G18: =+G13-G$11 -> 10.785 | H18: =+H13-H$11 -> 10.658333 | I18: =+I13-I$11 -> 10.399444 | J18: =+J13-J$11 -> 10.429444 | K18: =+K13-K$11 -> 10.959444 | ... W18: =+W13-W$11 -> 10.929444
B19: MG/Bht : W2 | D19: =+D14-D$11 -> 13.473889 | E19: =+E14-E$11 -> 13.622778 | F19: =+F14-F$11 -> 13.46 | G19: =+G14-G$11 -> 13.785 | H19: =+H14-H$11 -> 13.658333 | I19: =+I14-I$11 -> 13.399444 | J19: =+J14-J$11 -> 13.429444 | K19: =+K14-K$11 -> 13.959444 | ... W19: =+W14-W$11 -> 13.929444
B20: MG/Bht : R1 | D20: =+D15-D$11 -> 15.473889 | E20: =+E15-E$11 -> 15.622778 | F20: =+F15-F$11 -> 15.46 | G20: =+G15-G$11 -> 15.785 | H20: =+H15-H$11 -> 15.658333 | I20: =+I15-I$11 -> 15.399444 | J20: =+J15-J$11 -> 15.429444 | K20: =+K15-K$11 -> 15.959444 | ... W20: =+W15-W$11 -> 15.929444
B21: MG/Bht : R2 | D21: =+D16-D$11 -> 17.473889 | E21: =+E16-E$11 -> 17.622778 | F21: =+F16-F$11 -> 17.46 | G21: =+G16-G$11 -> 17.785 | H21: =+H16-H$11 -> 17.658333 | I21: =+I16-I$11 -> 17.399444 | J21: =+J16-J$11 -> 17.429444 | K21: =+K16-K$11 -> 17.959444 | ... W21: =+W16-W$11 -> 17.929444
B22: MG/% : SDM | D22: 0 | E22: 0 | F22: 0 | G22: 0 | H22: 0 | I22: 0 | J22: 0 | K22: 0 | L22: 0 | M22: 0 | N22: 0 | O22: 0 | P22: 0 | Q22: 0 | R22: 0 | S22: 0 | T22: 0 | U22: 0 | V22: 0 | W22: 0
B23: MG/% : W1 | D23: =+D18/D$13 -> 0.067140313 | E23: =+E18/E$13 -> 0.064380471 | F23: =+F18/F$13 -> 0.062261905 | G23: =+G18/G$13 -> 0.066574074 | H23: =+H18/H$13 -> 0.06832265 | I23: =+I18/I$13 -> 0.065819269 | J23: =+J18/J$13 -> 0.063984322 | K23: =+K18/K$13 -> 0.068071084 | ... W23: =+W18/W$13 -> 0.070060541
B24: MG/% : W2 | D24: =+D19/D$14 -> 0.08474144 | E24: =+E19/E$14 -> 0.081087963 | F24: =+F19/F$14 -> 0.07871345 | G24: =+G19/G$14 -> 0.083545455 | H24: =+H19/H$14 -> 0.085901468 | I24: =+I19/I$14 -> 0.083226363 | J24: =+J19/J$14 -> 0.080900268 | K24: =+K19/K$14 -> 0.085118564 | ... W24: =+W19/W$14 -> 0.087606569
B25: MG/% : R1 | D25: =+D20/D$15 -> 0.096111111 | E25: =+E20/E$15 -> 0.091898693 | F25: =+F20/F$15 -> 0.089364162 | G25: =+G20/G$15 -> 0.094520958 | H25: =+H20/H$15 -> 0.097256729 | I25: =+I20/I$15 -> 0.094475119 | J25: =+J20/J$15 -> 0.091841931 | K25: =+K20/K$15 -> 0.096141232 | ... W25: =+W20/W$15 -> 0.098940649
B26: MG/% : R2 | D26: =+D21/D$16 -> 0.10720177 | E26: =+E21/E$16 -> 0.10245801 | F26: =+F21/F$16 -> 0.099771429 | G26: =+G21/G$16 -> 0.10523669 | H26: =+H21/H$16 -> 0.10833333 | I26: =+I21/I$16 -> 0.10545118 | J26: =+J21/J$16 -> 0.10252614 | K26: =+K21/K$16 -> 0.10690146 | ... W26: =+W21/W$16 -> 0.10999659
A29: Y03094001604120120 | B29: SB 120x120 4 mm | D29: BKK | E29: CM | F29: CR | G29: PL | H29: NS | I29: KK | J29: SK | K29: UD | L29: UB | M29: NR | N29: RB | O29: PC | P29: BS | Q29: AY | R29: RY | S29: CB | T29: SR | U29: PK | V29: HY | W29: SB
B30: Price List | D30: 89 | E30: 89 | F30: 89 | G30: 89 | H30: 89 | I30: 89 | J30: 89 | K30: 89 | L30: 89 | M30: 89 | N30: 89 | O30: 89 | P30: 89 | Q30: 89 | R30: 89 | S30: 89 | W30: 89
B31: Discount | D31: 0.26 | E31: =D31 -> 0.26 | F31: =D31 -> 0.26 | G31: =D31 -> 0.26 | H31: =D31 -> 0.26 | I31: =D31 -> 0.26 | J31: =D31 -> 0.26 | K31: =D31 -> 0.26 | L31: =D31 -> 0.26 | M31: =D31 -> 0.26 | N31: =D31 -> 0.26 | O31: =D31 -> 0.26 | P31: =D31 -> 0.26 | Q31: =D31 -> 0.26 | R31: =D31 -> 0.26 | S31: =D31 -> 0.26 | W31: =J31 -> 0.26
B32: ค่าคลัง ตันละ 150 | D32: 0 | E32: 0 | F32: 0 | G32: 0 | H32: 0 | I32: 0 | J32: 0 | K32: 0 | L32: 0 | M32: 0 | N32: 0 | O32: 0 | P32: 0 | Q32: 0 | R32: 0 | S32: 0 | W32: 0
B33: RE (ex VAT) | D33: =D30-(D30*D31) -> 65.86 | E33: =E30-(E30*E31) -> 65.86 | F33: =F30-(F30*F31) -> 65.86 | G33: =G30-(G30*G31) -> 65.86 | H33: =H30-(H30*H31) -> 65.86 | I33: =I30-(I30*I31) -> 65.86 | J33: =J30-(J30*J31) -> 65.86 | K33: =K30-(K30*K31) -> 65.86 | ... S33: =S30-(S30*S31) -> 65.86 | T33: 72.05 | U33: 72.05 | V33: 72.05 | W33: =W30-(W30*W31) -> 65.86
B34: VAT | C34: 0.07 | D34: =D33*$C34 -> 4.6102 | E34: =E33*$C34 -> 4.6102 | F34: =F33*$C34 -> 4.6102 | G34: =G33*$C34 -> 4.6102 | H34: =H33*$C34 -> 4.6102 | I34: =I33*$C34 -> 4.6102 | J34: =J33*$C34 -> 4.6102 | K34: =K33*$C34 -> 4.6102 | ... W34: =W33*$C34 -> 4.6102
B35: Net Price (inc VAT) | D35: =D33+D34 -> 70.4702 | E35: =E33+E34 -> 70.4702 | F35: =F33+F34 -> 70.4702 | G35: =G33+G34 -> 70.4702 | H35: =H33+H34 -> 70.4702 | I35: =I33+I34 -> 70.4702 | J35: =J33+J34 -> 70.4702 | K35: =K33+K34 -> 70.4702 | ... W35: =W33+W34 -> 70.4702
B36: Transportation | D36: =Y38 -> 3.4805556 | E36: =Z38 -> 7.9061111 | F36: =AA38 -> 9.4875 | G36: =AB38 -> 6.325 | H36: =AC38 -> 3.3883333 | I36: =AD38 -> 4.5177778 | J36: =AE38 -> 7.0027778 | K36: =AF38 -> 5.7377778 | ... W36: =AR38 -> 3.2527778 | Y36: 12530 | Z36: 28462 | AA36: 34155 | AB36: 22770 | AC36: 12198 | AD36: 16264 | AE36: 25210 | AF36: 20656 | AG36: 24396 | AH36: 11710 | AI36: 13012 | AJ36: 30581 | AK36: 11710 | AL36: 11710 | AM36: 15451 | AN36: 14638 | AP36: 30581 | AR36: 11710
B37: COGS | D37: =SUM(D35:D36) -> 73.950756 | E37: =SUM(E35:E36) -> 78.376311 | F37: =SUM(F35:F36) -> 79.9577 | G37: =SUM(G35:G36) -> 76.7952 | H37: =SUM(H35:H36) -> 73.858533 | I37: =SUM(I35:I36) -> 74.987978 | J37: =SUM(J35:J36) -> 77.472978 | K37: =SUM(K35:K36) -> 76.207978 | ... W37: =SUM(W35:W36) -> 73.722978 | Y37: 3600 | Z37: 3600 | AA37: 3600 | AB37: 3600 | AC37: 3600 | AD37: 3600 | AE37: 3600 | AF37: 3600 | AG37: 3600 | AH37: 3600 | AI37: 3600 | AJ37: 3600 | AK37: 3600 | AL37: 3600 | AM37: 3600 | AN37: 3600 | AP37: 3600 | AR37: 3600
B38: Promotion Rebate | Y38: =Y36/Y37 -> 3.4805556 | Z38: =Z36/Z37 -> 7.9061111 | AA38: =AA36/AA37 -> 9.4875 | AB38: =AB36/AB37 -> 6.325 | AC38: =AC36/AC37 -> 3.3883333 | AD38: =AD36/AD37 -> 4.5177778 | AE38: =AE36/AE37 -> 7.0027778 | AF38: =AF36/AF37 -> 5.7377778 | ... AN38: =AN36/AN37 -> 4.0661111 | AP38: =AP36/AP37 -> 8.4947222 | AR38: =AR36/AR37 -> 3.2527778
B39: Net Cost | D39: =D37+D38 -> 73.950756 | E39: =E37+E38 -> 78.376311 | F39: =F37+F38 -> 79.9577 | G39: =G37+G38 -> 76.7952 | H39: =H37+H38 -> 73.858533 | I39: =I37+I38 -> 74.987978 | J39: =J37+J38 -> 77.472978 | K39: =K37+K38 -> 76.207978 | ... W39: =W37+W38 -> 73.722978
B40: Price : SDM | D40: 0 | E40: 0 | F40: 0 | G40: 0 | H40: 0 | I40: 0 | J40: 0 | K40: 0 | L40: 0 | M40: 0 | N40: 0 | O40: 0 | P40: 0 | Q40: 0 | R40: 0 | S40: 0 | T40: 0 | U40: 0 | V40: 0 | W40: 0
B41: Price : W1 | D41: 79 | E41: 84 | F41: 85 | G41: 82 | H41: 79 | I41: 80 | J41: 83 | K41: 82 | L41: 83 | M41: 79 | N41: 80 | O41: 84 | P41: 79 | Q41: 79 | R41: 80 | S41: 80 | T41: 83 | U41: 91 | V41: 83 | W41: 79
B42: Price : W2 | D42: 81 | E42: 86 | F42: 87 | G42: 84 | H42: 81 | I42: 82 | J42: 85 | K42: 84 | L42: 85 | M42: 81 | N42: 82 | O42: 86 | P42: 81 | Q42: 81 | R42: 82 | S42: 82 | T42: 85 | U42: 93 | V42: 85 | W42: 81
...

Sheet Rockwool
A1: Y06135105682060400 | B1: Rockchill | D1: BKK | E1: CM | F1: CR | G1: PL | H1: NS | I1: KK | J1: SK | K1: UD | L1: UB | M1: NR | N1: RB | O1: PC | P1: BS | Q1: AY | R1: RY | S1: CB | T1: SR | U1: PK | V1: HY | W1: SB
B2: Price List
B3: Discount
D4: =D2*(1-D3) -> 0 | E4: =E2*(1-E3) -> 0 | F4: =F2*(1-F3) -> 0 | G4: =G2*(1-G3) -> 0 | H4: =H2*(1-H3) -> 0 | I4: =I2*(1-I3) -> 0 | J4: =J2*(1-J3) -> 0 | K4: =K2*(1-K3) -> 0 | ... W4: =W2*(1-W3) -> 0
B5: Discount | C5: 0.02
B6: RE (ex VAT) | D6: =D4-D5 -> 0 | E6: =E4-E5 -> 0 | F6: =F4-F5 -> 0 | G6: =G4-G5 -> 0 | H6: =H4-H5 -> 0 | I6: =I4-I5 -> 0 | J6: =J4-J5 -> 0 | K6: =K4-K5 -> 0 | ... W6: =W4-W5 -> 0
B7: VAT | C7: 0.07 | D7: =D6*$C7 -> 0 | E7: =E6*$C7 -> 0 | F7: =F6*$C7 -> 0 | G7: =G6*$C7 -> 0 | H7: =H6*$C7 -> 0 | I7: =I6*$C7 -> 0 | J7: =J6*$C7 -> 0 | K7: =K6*$C7 -> 0 | ... W7: =W6*$C7 -> 0
B8: Net Price (inc VAT) | D8: =D6+D7 -> 0 | E8: =E6+E7 -> 0 | F8: =F6+F7 -> 0 | G8: =G6+G7 -> 0 | H8: =H6+H7 -> 0 | I8: =I6+I7 -> 0 | J8: =J6+J7 -> 0 | K8: =K6+K7 -> 0 | ... W8: =W6+W7 -> 0
B9: Transportation
B10: COGS | D10: =SUM(D8:D9) -> 0 | E10: =SUM(E8:E9) -> 0 | F10: =SUM(F8:F9) -> 0 | G10: =SUM(G8:G9) -> 0 | H10: =SUM(H8:H9) -> 0 | I10: =SUM(I8:I9) -> 0 | J10: =SUM(J8:J9) -> 0 | K10: =SUM(K8:K9) -> 0 | ... W10: =SUM(W8:W9) -> 0
B11: Promotion Rebate
B12: Net Cost | D12: =SUM(D10:D11) -> 0 | E12: =SUM(E10:E11) -> 0 | F12: =SUM(F10:F11) -> 0 | G12: =SUM(G10:G11) -> 0 | H12: =SUM(H10:H11) -> 0 | I12: =SUM(I10:I11) -> 0 | J12: =SUM(J10:J11) -> 0 | K12: =SUM(K10:K11) -> 0 | ... W12: =SUM(W10:W11) -> 0
B13: Price : SDM | D13: 0 | E13: 0 | F13: 0 | G13: 0 | H13: 0 | I13: 0 | J13: 0 | K13: 0 | L13: 0 | M13: 0 | N13: 0 | O13: 0 | P13: 0 | Q13: 0 | R13: 0 | S13: 0 | T13: 0 | U13: 0 | V13: 0 | W13: 0
B14: Price : W1 | D14: 308.9625 | E14: 338.3625 | F14: 0 | G14: 335.3595 | H14: 324.6705 | I14: 330.9495 | J14: 338.3625 | K14: 0 | L14: 0 | M14: 0 | N14: 319.515 | O14: 331.044 | P14: 308.9625 | Q14: 317.3625 | R14: 308.9625 | S14: 308.9625 | T14: 0 | U14: 359.4465 | V14: 0 | W14: 317.3625
B15: Price : W2 | D15: 323.675 | E15: 354.475 | F15: 0 | G15: 351.329 | H15: 340.131 | I15: 346.709 | J15: 354.475 | K15: 0 | L15: 0 | M15: 0 | N15: 334.73 | O15: 346.808 | P15: 323.675 | Q15: 332.475 | R15: 323.675 | S15: 323.675 | T15: 0 | U15: 376.563 | V15: 0 | W15: 332.475
B16: Price : R1 | D16: 338.3875 | E16: 370.5875 | F16: 0 | G16: 367.2985 | H16: 349.4073 | I16: 356.1647 | J16: 370.5875 | K16: 0 | L16: 0 | M16: 0 | N16: 349.945 | O16: 362.572 | P16: 338.3875 | Q16: 347.5875 | R16: 338.3875 | S16: 338.3875 | T16: 0 | U16: 393.6795 | V16: 0 | W16: 347.5875
B17: Price : R2 | D17: 353.1 | E17: 386.7 | F17: 0 | G17: 383.268 | H17: 355.5915 | I17: 362.4685 | J17: 386.7 | K17: 0 | L17: 0 | M17: 0 | N17: 365.16 | O17: 378.336 | P17: 353.1 | Q17: 362.7 | R17: 353.1 | S17: 353.1 | T17: 0 | U17: 410.796 | V17: 0 | W17: 362.7
B18: MG/Bht : SDM | D18: 0 | E18: 0 | F18: 0 | G18: 0 | H18: 0 | I18: 0 | J18: 0 | K18: 0 | L18: 0 | M18: 0 | N18: 0 | O18: 0 | P18: 0 | Q18: 0 | R18: 0 | S18: 0 | T18: 0 | U18: 0 | V18: 0 | W18: 0
B19: MG/Bht : W1 | D19: =D14-D12 -> 308.9625 | E19: =E14-E12 -> 338.3625 | F19: =F14-F12 -> 0 | G19: =G14-G12 -> 335.3595 | H19: =H14-H12 -> 324.6705 | I19: =I14-I12 -> 330.9495 | J19: =J14-J12 -> 338.3625 | K19: =K14-K12 -> 0 | ... W19: =W14-W12 -> 317.3625
B20: MG/Bht : W2 | D20: =+D15-D$12 -> 323.675 | E20: =+E15-E12 -> 354.475 | F20: =+F15-F12 -> 0 | G20: =+G15-G12 -> 351.329 | H20: =+H15-H12 -> 340.131 | I20: =+I15-I12 -> 346.709 | J20: =+J15-J12 -> 354.475 | K20: =+K15-K12 -> 0 | L20: =+L15-L12 -> 0 | ... P20: =+P15-P12 -> 323.675 | Q20: =+Q15-Q$12 -> 332.475 | R20: =+R15-R12 -> 323.675 | S20: =+S15-S12 -> 323.675 | T20: =+T15-T12 -> 0 | U20: =+U15-U12 -> 376.563 | V20: =+V15-V12 -> 0 | W20: =+W15-W12 -> 332.475
B21: MG/Bht : R1 | D21: =+D16-D$12 -> 338.3875 | E21: =+E16-E12 -> 370.5875 | F21: =+F16-F12 -> 0 | G21: =+G16-G12 -> 367.2985 | H21: =+H16-H12 -> 349.4073 | I21: =+I16-I12 -> 356.1647 | J21: =+J16-J12 -> 370.5875 | K21: =+K16-K12 -> 0 | L21: =+L16-L12 -> 0 | ... P21: =+P16-P12 -> 338.3875 | Q21: =+Q16-Q$12 -> 347.5875 | R21: =+R16-R12 -> 338.3875 | S21: =+S16-S12 -> 338.3875 | T21: =+T16-T12 -> 0 | U21: =+U16-U12 -> 393.6795 | V21: =+V16-V12 -> 0 | W21: =+W16-W12 -> 347.5875
B22: MG/Bht : R2 | D22: =+D17-D$12 -> 353.1 | E22: =+E17-E12 -> 386.7 | F22: =+F17-F12 -> 0 | G22: =+G17-G12 -> 383.268 | H22: =+H17-H12 -> 355.5915 | I22: =+I17-I12 -> 362.4685 | J22: =+J17-J12 -> 386.7 | K22: =+K17-K12 -> 0 | L22: =+L17-L12 -> 0 | ... P22: =+P17-P12 -> 353.1 | Q22: =+Q17-Q$12 -> 362.7 | R22: =+R17-R12 -> 353.1 | S22: =+S17-S12 -> 353.1 | T22: =+T17-T12 -> 0 | U22: =+U17-U12 -> 410.796 | V22: =+V17-V12 -> 0 | W22: =+W17-W12 -> 362.7
B23: MG/% : SDM | D23: 0 | E23: 0 | F23: 0 | G23: 0 | H23: 0 | I23: 0 | J23: 0 | K23: 0 | L23: 0 | M23: 0 | N23: 0 | O23: 0 | P23: 0 | Q23: 0 | R23: 0 | S23: 0 | T23: 0 | U23: 0 | V23: 0 | W23: 0
B24: MG/% : W1 | D24: =+D19/D12 -> #DIV/0! | E24: =+E19/E12 -> #DIV/0! | F24: =+F19/F12 -> #DIV/0! | G24: =+G19/G12 -> #DIV/0! | H24: =+H19/H12 -> #DIV/0! | I24: =+I19/I12 -> #DIV/0! | J24: =+J19/J12 -> #DIV/0! | K24: =+K19/K12 -> #DIV/0! | ... W24: =+W19/W12 -> #DIV/0!
B25: MG/% : W2 | D25: =+D20/D12 -> #DIV/0! | E25: =+E20/E12 -> #DIV/0! | F25: =+F20/F12 -> #DIV/0! | G25: =+G20/G12 -> #DIV/0! | H25: =+H20/H12 -> #DIV/0! | I25: =+I20/I12 -> #DIV/0! | J25: =+J20/J12 -> #DIV/0! | K25: =+K20/K12 -> #DIV/0! | ... W25: =+W20/W12 -> #DIV/0!
B26: MG/% : R1 | D26: =+D21/D12 -> #DIV/0! | E26: =+E21/E12 -> #DIV/0! | F26: =+F21/F12 -> #DIV/0! | G26: =+G21/G12 -> #DIV/0! | H26: =+H21/H12 -> #DIV/0! | I26: =+I21/I12 -> #DIV/0! | J26: =+J21/J12 -> #DIV/0! | K26: =+K21/K12 -> #DIV/0! | ... W26: =+W21/W12 -> #DIV/0!
B27: MG/% : R2 | D27: =+D22/D12 -> #DIV/0! | E27: =+E22/E12 -> #DIV/0! | F27: =+F22/F12 -> #DIV/0! | G27: =+G22/G12 -> #DIV/0! | H27: =+H22/H12 -> #DIV/0! | I27: =+I22/I12 -> #DIV/0! | J27: =+J22/J12 -> #DIV/0! | K27: =+K22/K12 -> #DIV/0! | ... W27: =+W22/W12 -> #DIV/0!
A29: Y06135005881060120 | B29: Safe 'n' Silent Pro 330 หนา 50 มม. 60*120 | D29: BKK | E29: CM | F29: CR | G29: PL | H29: NS | I29: KK | J29: SK | K29: UD | L29: UB | M29: NR | N29: RB | O29: PC | P29: BS | Q29: AY | R29: RY | S29: CB | T29: SR | U29: PK | V29: HY | W29: SB
B30: Price List
B31: Discount
D32: =D30*(1-D31) -> 0 | E32: =E30*(1-E31) -> 0 | F32: =F30*(1-F31) -> 0 | G32: =G30*(1-G31) -> 0 | H32: =H30*(1-H31) -> 0 | I32: =I30*(1-I31) -> 0 | J32: =J30*(1-J31) -> 0 | K32: =K30*(1-K31) -> 0 | ... W32: =W30*(1-W31) -> 0
B33: Discount | C33: 0.02
B34: RE (ex VAT) | D34: =D32-D33 -> 0 | E34: =E32-E33 -> 0 | F34: =F32-F33 -> 0 | G34: =G32-G33 -> 0 | H34: =H32-H33 -> 0 | I34: =I32-I33 -> 0 | J34: =J32-J33 -> 0 | K34: =K32-K33 -> 0 | ... W34: =W32-W33 -> 0
B35: VAT | C35: 0.07 | D35: =D34*$C35 -> 0 | E35: =E34*$C35 -> 0 | F35: =F34*$C35 -> 0 | G35: =G34*$C35 -> 0 | H35: =H34*$C35 -> 0 | I35: =I34*$C35 -> 0 | J35: =J34*$C35 -> 0 | K35: =K34*$C35 -> 0 | ... W35: =W34*$C35 -> 0
B36: Net Price (inc VAT) | D36: =D34+D35 -> 0 | E36: =E34+E35 -> 0 | F36: =F34+F35 -> 0 | G36: =G34+G35 -> 0 | H36: =H34+H35 -> 0 | I36: =I34+I35 -> 0 | J36: =J34+J35 -> 0 | K36: =K34+K35 -> 0 | ... W36: =W34+W35 -> 0
B37: Transportation | E37: 4.5 | G37: 11.67 | H37: 6.94 | I37: 9.72 | N37: 4.67 | O37: 9.76 | P37: 0 | Q37: 2.87 | U37: 22.32 | W37: 3.71
B38: COGS | D38: =SUM(D36:D37) -> 0 | E38: =SUM(E36:E37) -> 4.5 | F38: =SUM(F36:F37) -> 0 | G38: =SUM(G36:G37) -> 11.67 | H38: =SUM(H36:H37) -> 6.94 | I38: =SUM(I36:I37) -> 9.72 | J38: =SUM(J36:J37) -> 0 | K38: =SUM(K36:K37) -> 0 | ... W38: =SUM(W36:W37) -> 3.71
B39: Promotion Rebate
B40: Net Cost | D40: =SUM(D38:D39) -> 0 | E40: =SUM(E38:E39) -> 4.5 | F40: =SUM(F38:F39) -> 0 | G40: =SUM(G38:G39) -> 11.67 | H40: =SUM(H38:H39) -> 6.94 | I40: =SUM(I38:I39) -> 9.72 | J40: =SUM(J38:J39) -> 0 | K40: =SUM(K38:K39) -> 0 | ... W40: =SUM(W38:W39) -> 3.71
B41: Price : SDM | D41: 0 | E41: 0 | F41: 0 | G41: 0 | H41: 0 | I41: 0 | J41: 0 | K41: 0 | L41: 0 | M41: 0 | N41: 0 | O41: 0 | P41: 0 | Q41: 0 | R41: 0 | S41: 0 | T41: 0 | U41: 0 | V41: 0 | W41: 0
...

Sheet BKK DCM
A1: Internal Memo | E1: No.
A2: To : | B2: ผู้จัดการภาค / ผู้จัดการเขต | E2: Date :
A3: RE :
A4: หมายเหตุ : | B4: 1 | C4: ราคาขายข้างต้นรวม VAT
B5: 2 | C5: หากราคาข้างต้นสูง ไม่สามารถขายได้ โปรดสอบถาม ผจก.PM
B6: 3 | C6: ราคาขายข้างต้นให้ถือเป็นราคาขายต่ำสุด สามารถขายที่ราคาสูงกว่านี้ได้ ขึ้นอยู่กับแต่ละพื้นที่
B7: 4 | C7: ปริมาณการขายส่งแผ่น 120x240 ขั้นต่ำ 400 แผ่น : เดือน
B8: 5 | C8: ราคา RE (EX VAT) และไม่รวมค่าขนส่ง ยังไม่หักรีเบทประจำเดือน
A10: BKK Price | D10: BKK
A11: Y 1: Gypsum | C11: WIP | D11: WIPR | E11: WIPRSO
B12: W1 | C12: W2 | D12: R1 | E12: R2
A13: ยิปซัม ธรรมดา 9 มม. ขอบเรียบ/ลาด | B13: ='Formular 4 step Y1'!D14 -> 124 | C13: ='Formular 4 step Y1'!D15 -> 125 | D13: ='Formular 4 step Y1'!D16 -> 126 | E13: ='Formular 4 step Y1'!D17 -> 127
A14: ยิปซัม ธรรมดา 9 มม. ขอบลาด 4 ด้าน | B14: ='Formular 4 step Y1'!D39 -> 124 | C14: ='Formular 4 step Y1'!D40 -> 125 | D14: ='Formular 4 step Y1'!D41 -> 126 | E14: ='Formular 4 step Y1'!D42 -> 127
A15: ยิปซัม ทนชื้น/ฟลอยด์ 9 มม. ขอบเรียบ/ลาด | B15: ='Formular 4 step Y1'!D64 -> 185 | C15: ='Formular 4 step Y1'!D65 -> 186 | D15: ='Formular 4 step Y1'!D66 -> 187 | E15: ='Formular 4 step Y1'!D67 -> 188
A16: ยิปซัม ทนชื้น/ฟลอยด์ 9 มม. ขอบลาด 4 ด้าน | B16: ='Formular 4 step Y1'!D89 -> 184 | C16: ='Formular 4 step Y1'!D90 -> 185 | D16: ='Formular 4 step Y1'!D91 -> 186 | E16: ='Formular 4 step Y1'!D92 -> 187
A17: ยิปซัม ธรรมดา 12 มม. ขอบเรียบ/ลาด | B17: ='Formular 4 step Y1'!D114 -> 143 | C17: ='Formular 4 step Y1'!D115 -> 144 | D17: ='Formular 4 step Y1'!D116 -> 145 | E17: ='Formular 4 step Y1'!D117 -> 146
A18: ยิปซัม ทนชื้น/ฟลอยด์ 12 มม. ขอบเรียบ/ลาด | B18: ='Formular 4 step Y1'!D139 -> 206 | C18: ='Formular 4 step Y1'!D140 -> 207 | D18: ='Formular 4 step Y1'!D141 -> 208 | E18: ='Formular 4 step Y1'!D142 -> 209
A19: ยิปซัม ธรรมดา 15 มม. ขอบลาด | B19: ='Formular 4 step Y1'!D838 -> 205 | C19: ='Formular 4 step Y1'!D839 -> 206 | D19: ='Formular 4 step Y1'!D840 -> 207 | E19: ='Formular 4 step Y1'!D841 -> 208
A20: ทนไฟ 12 มม. | B20: ='Formular 4 step Y1'!D164 -> 241 | C20: ='Formular 4 step Y1'!D165 -> 244 | D20: ='Formular 4 step Y1'!D166 -> 249 | E20: ='Formular 4 step Y1'!D167 -> 254
A21: ทนไฟ 15 มม. | B21: ='Formular 4 step Y1'!D189 -> 269 | C21: ='Formular 4 step Y1'!D190 -> 272 | D21: ='Formular 4 step Y1'!D191 -> 277 | E21: ='Formular 4 step Y1'!D192 -> 282
A22: ยิปซัมเฟล็กบอร์ด(ดัดโค้ง) 6 มม. 120*240 มม. | B22: ='Formular 4 step Y1'!D863 -> 178.69762 | C22: ='Formular 4 step Y1'!D864 -> 180.35223 | D22: ='Formular 4 step Y1'!D865 -> 185.31605 | E22: ='Formular 4 step Y1'!D866 -> 190.27987
A23: อี่ซี่บอร์ท / คนอฟ | B23: ='Formular 4 step Y1'!D738 -> 101 | C23: ='Formular 4 step Y1'!D739 -> 102 | D23: ='Formular 4 step Y1'!D740 -> 103 | E23: ='Formular 4 step Y1'!D741 -> 104
A24: อี่ซี่บอร์ท/คนอฟ ทนชื้น / ฟอล์ย | B24: ='Formular 4 step Y1'!D763 -> 156 | C24: ='Formular 4 step Y1'!D764 -> 157 | D24: ='Formular 4 step Y1'!D765 -> 158 | E24: ='Formular 4 step Y1'!D766 -> 159
A25: เวเทอร์บล็อค W0 | B25: ='Formular 4 step Y1'!D788 -> 268 | C25: ='Formular 4 step Y1'!D789 -> 269 | D25: ='Formular 4 step Y1'!D790 -> 270 | E25: ='Formular 4 step Y1'!D791 -> 271
A26: เวเทอร์บล็อค W1 | B26: ='Formular 4 step Y1'!D813 -> 425 | C26: ='Formular 4 step Y1'!D814 -> 426 | D26: ='Formular 4 step Y1'!D815 -> 427 | E26: ='Formular 4 step Y1'!D816 -> 428
A27: ยิปซัมลดเสียงสะท้อน เอคโค่บล็อค (R1,R2,R8,S8) | B27: ='Formular 4 step Y1'!D214 -> 904 | C27: ='Formular 4 step Y1'!D215 -> 907 | D27: ='Formular 4 step Y1'!D216 -> 917 | E27: ='Formular 4 step Y1'!D217 -> 927
A28: Paper touch ลวดลาย 60*60*8 mm. | B28: ='Formular 4 step Y1'!D239 -> 20.902296 | C28: ='Formular 4 step Y1'!D240 -> 22 | D28: ='Formular 4 step Y1'!D241 -> 23 | E28: ='Formular 4 step Y1'!D242 -> 24
A29: Paper touch หยาดเพชร 60*60*8 mm. | B29: ='Formular 4 step Y1'!D264 -> 20.189248 | C29: ='Formular 4 step Y1'!D265 -> 21 | D29: ='Formular 4 step Y1'!D266 -> 22 | E29: ='Formular 4 step Y1'!D267 -> 23
A30: Paper touch หยาดเพชร 60*60*8 mm. กันร้อน | B30: ='Formular 4 step Y1'!D289 -> 23.754488 | C30: ='Formular 4 step Y1'!D290 -> 25 | D30: ='Formular 4 step Y1'!D291 -> 26 | E30: ='Formular 4 step Y1'!D292 -> 27
A31: Color touch สีมุก/สีเพชร 60x60*9 mm. | B31: ='Formular 4 step Y1'!D313 -> 23 | C31: ='Formular 4 step Y1'!D314 -> 24 | D31: ='Formular 4 step Y1'!D315 -> 25 | E31: ='Formular 4 step Y1'!D316 -> 26
A32: Color touch สีมุก/สีเพชร 60x120*9 mm. | B32: ='Formular 4 step Y1'!D338 -> 46 | C32: ='Formular 4 step Y1'!D339 -> 47 | D32: ='Formular 4 step Y1'!D340 -> 48 | E32: ='Formular 4 step Y1'!D341 -> 50
A33: Color touch สีมุก/สีเพชร 60x120*12 mm. | B33: ='Formular 4 step Y1'!D888 -> 46.911609 | C33: ='Formular 4 step Y1'!D889 -> 47.5 | D33: ='Formular 4 step Y1'!D890 -> 48.202754 | E33: ='Formular 4 step Y1'!D891 -> 49.493899
A34: Color touch สีมุก/สีเพชร 60x60*9 mm. ทนชื้น | B34: ='Formular 4 step Y1'!D363 -> 28 | C34: ='Formular 4 step Y1'!D364 -> 29 | D34: ='Formular 4 step Y1'!D365 -> 31 | E34: ='Formular 4 step Y1'!D366 -> 32
A35: Color touch สีมุก/สีเพชร 60x120*9 mm. ทนชื้น | B35: ='Formular 4 step Y1'!D388 -> 57 | C35: ='Formular 4 step Y1'!D389 -> 58 | D35: ='Formular 4 step Y1'!D390 -> 59 | E35: ='Formular 4 step Y1'!D391 -> 61
A36: Color touch สีมุก/สีเพชร 60x120*12 mm. ทนชื้น | B36: ='Formular 4 step Y1'!D913 -> 63.551024 | C36: ='Formular 4 step Y1'!D914 -> 64.5 | D36: ='Formular 4 step Y1'!D915 -> 65.300135 | E36: ='Formular 4 step Y1'!D916 -> 67.049246
A37: เซิฟบอร์ด ขนาด 30 ซม. | B37: ='Formular 4 step Y1'!D413 -> 189 | C37: ='Formular 4 step Y1'!D414 -> 190 | D37: ='Formular 4 step Y1'!D415 -> 195 | E37: ='Formular 4 step Y1'!D416 -> 200
A38: เซิฟบอร์ด ขนาด 45 ซม. | B38: ='Formular 4 step Y1'!D438 -> 260 | C38: ='Formular 4 step Y1'!D439 -> 262 | D38: ='Formular 4 step Y1'!D440 -> 264 | E38: ='Formular 4 step Y1'!D441 -> 266
A39: เซิฟบอร์ด ขนาด 60 ซม. | B39: ='Formular 4 step Y1'!D463 -> 319 | C39: ='Formular 4 step Y1'!D464 -> 321 | D39: ='Formular 4 step Y1'!D465 -> 323 | E39: ='Formular 4 step Y1'!D466 -> 325
A40: เซิฟบอร์ด ขนาด 60*120 ซม. | B40: ='Formular 4 step Y1'!D488 -> 771 | C40: ='Formular 4 step Y1'!D489 -> 773 | D40: ='Formular 4 step Y1'!D490 -> 778 | E40: ='Formular 4 step Y1'!D491 -> 783
A41: เซิฟบอร์ด ขนาด 30 ซม. ทนชื้น | B41: ='Formular 4 step Y1'!D513 -> 257 | C41: ='Formular 4 step Y1'!D514 -> 259 | D41: ='Formular 4 step Y1'!D515 -> 262 | E41: ='Formular 4 step Y1'!D516 -> 264
...

Sheet N DCM
A1: Internal Memo | G1: No.
A2: To : | E2: ผู้จัดการภาค / ผู้จัดการเขต | G2: Date :
A3: RE :
A4: หมายเหตุ : | D4: 1 | E4: ราคาขายข้างต้นรวม VAT
D5: 2 | E5: หากราคาข้างต้นสูง ไม่สามารถขายได้ โปรดสอบถาม ผจก.PM
D6: 3 | E6: ราคาขายข้างต้นให้ถือเป็นราคาขายต่ำสุด สามารถขายที่ราคาสูงกว่านี้ได้ ขึ้นอยู่กับแต่ละพื้นที่
D7: 4 | E7: ปริมาณการขายส่งแผ่น 120x240 ขั้นต่ำ 400 แผ่น : เดือน
D8: 5 | E8: ราคา RE (EX VAT) และไม่รวมค่าขนส่ง ยังไม่หักรีเบทประจำเดือน
A10: N Price | D10: CM | H10: CR | L10: PL | P10: NS
A11: Y 1: Gypsum | C11: WIP | D11: WIPR | E11: WIPRSO | G11: WIP | H11: WIPR | I11: WIPRSO | K11: WIP | L11: WIPR | M11: WIPRSO | O11: WIP | P11: WIPR | Q11: WIPRSO
B12: W1 | C12: W2 | D12: R1 | E12: R2 | F12: W1 | G12: W2 | H12: R1 | I12: R2 | J12: W1 | K12: W2 | L12: R1 | M12: R2 | N12: W1 | O12: W2 | P12: R1 | Q12: R2
A13: ยิปซัม ธรรมดา 9 มม. ขอบเรียบ/ลาด | B13: ='Formular 4 step Y1'!E14 -> 136 | C13: ='Formular 4 step Y1'!E15 -> 137 | D13: ='Formular 4 step Y1'!E16 -> 138 | E13: ='Formular 4 step Y1'!E17 -> 139 | F13: ='Formular 4 step Y1'!F14 -> 139 | G13: ='Formular 4 step Y1'!F15 -> 140 | H13: ='Formular 4 step Y1'!F16 -> 141 | I13: ='Formular 4 step Y1'!F17 -> 142 | J13: ='Formular 4 step Y1'!G14 -> 134 | K13: ='Formular 4 step Y1'!G15 -> 135 | L13: ='Formular 4 step Y1'!G16 -> 136 | M13: ='Formular 4 step Y1'!G17 -> 137 | N13: ='Formular 4 step Y1'!H14 -> 129 | O13: ='Formular 4 step Y1'!H15 -> 130 | P13: ='Formular 4 step Y1'!H16 -> 131 | Q13: ='Formular 4 step Y1'!H17 -> 132
A14: ยิปซัม ธรรมดา 9 มม. ขอบลาด 4 ด้าน | B14: ='Formular 4 step Y1'!E39 -> 139 | C14: ='Formular 4 step Y1'!E40 -> 140 | D14: ='Formular 4 step Y1'!E41 -> 141 | E14: ='Formular 4 step Y1'!E42 -> 142 | F14: ='Formular 4 step Y1'!F39 -> 141 | G14: ='Formular 4 step Y1'!F40 -> 142 | H14: ='Formular 4 step Y1'!F41 -> 143 | I14: ='Formular 4 step Y1'!F42 -> 144 | J14: ='Formular 4 step Y1'!G39 -> 136 | K14: ='Formular 4 step Y1'!G40 -> 137 | L14: ='Formular 4 step Y1'!G41 -> 138 | M14: ='Formular 4 step Y1'!G42 -> 139 | N14: ='Formular 4 step Y1'!H39 -> 132 | O14: ='Formular 4 step Y1'!H40 -> 133 | P14: ='Formular 4 step Y1'!H41 -> 134 | Q14: ='Formular 4 step Y1'!H42 -> 135
A15: ยิปซัม ทนชื้น/ฟลอยด์ 9 มม. ขอบเรียบ/ลาด | B15: ='Formular 4 step Y1'!E64 -> 202 | C15: ='Formular 4 step Y1'!E65 -> 203 | D15: ='Formular 4 step Y1'!E66 -> 204 | E15: ='Formular 4 step Y1'!E67 -> 205 | F15: ='Formular 4 step Y1'!F64 -> 204 | G15: ='Formular 4 step Y1'!F65 -> 205 | H15: ='Formular 4 step Y1'!F66 -> 206 | I15: ='Formular 4 step Y1'!F67 -> 207 | J15: ='Formular 4 step Y1'!G64 -> 199 | K15: ='Formular 4 step Y1'!G65 -> 200 | L15: ='Formular 4 step Y1'!G66 -> 201 | M15: ='Formular 4 step Y1'!G67 -> 202 | N15: ='Formular 4 step Y1'!H64 -> 195 | O15: ='Formular 4 step Y1'!H65 -> 196 | P15: ='Formular 4 step Y1'!H66 -> 197 | Q15: ='Formular 4 step Y1'!H67 -> 198
A16: ยิปซัม ทนชื้น/ฟลอยด์ 9 มม. ขอบลาด 4 ด้าน | B16: ='Formular 4 step Y1'!E89 -> 201 | C16: ='Formular 4 step Y1'!E90 -> 202 | D16: ='Formular 4 step Y1'!E91 -> 203 | E16: ='Formular 4 step Y1'!E92 -> 204 | F16: ='Formular 4 step Y1'!F89 -> 203 | G16: ='Formular 4 step Y1'!F90 -> 204 | H16: ='Formular 4 step Y1'!F91 -> 205 | I16: ='Formular 4 step Y1'!F92 -> 206 | J16: ='Formular 4 step Y1'!G89 -> 198 | K16: ='Formular 4 step Y1'!G90 -> 199 | L16: ='Formular 4 step Y1'!G91 -> 200 | M16: ='Formular 4 step Y1'!G92 -> 201 | N16: ='Formular 4 step Y1'!H89 -> 194 | O16: ='Formular 4 step Y1'!H90 -> 195 | P16: ='Formular 4 step Y1'!H91 -> 196 | Q16: ='Formular 4 step Y1'!H92 -> 197
A17: ยิปซัม ธรรมดา 12 มม. ขอบเรียบ/ลาด | B17: ='Formular 4 step Y1'!E114 -> 165 | C17: ='Formular 4 step Y1'!E115 -> 166 | D17: ='Formular 4 step Y1'!E116 -> 167 | E17: ='Formular 4 step Y1'!E117 -> 168 | F17: ='Formular 4 step Y1'!F114 -> 169 | G17: ='Formular 4 step Y1'!F115 -> 170 | H17: ='Formular 4 step Y1'!F116 -> 171 | I17: ='Formular 4 step Y1'!F117 -> 172 | J17: ='Formular 4 step Y1'!G114 -> 162 | K17: ='Formular 4 step Y1'!G115 -> 163 | L17: ='Formular 4 step Y1'!G116 -> 164 | M17: ='Formular 4 step Y1'!G117 -> 165 | N17: ='Formular 4 step Y1'!H114 -> 155 | O17: ='Formular 4 step Y1'!H115 -> 156 | P17: ='Formular 4 step Y1'!H116 -> 157 | Q17: ='Formular 4 step Y1'!H117 -> 158
A18: ยิปซัม ทนชื้น/ฟลอยด์ 12 มม. ขอบเรียบ/ลาด | B18: ='Formular 4 step Y1'!E139 -> 228 | C18: ='Formular 4 step Y1'!E140 -> 229 | D18: ='Formular 4 step Y1'!E141 -> 230 | E18: ='Formular 4 step Y1'!E141 -> 230 | F18: ='Formular 4 step Y1'!F139 -> 231 | G18: ='Formular 4 step Y1'!F140 -> 232 | H18: ='Formular 4 step Y1'!F141 -> 233 | I18: ='Formular 4 step Y1'!F141 -> 233 | J18: ='Formular 4 step Y1'!G139 -> 224 | K18: ='Formular 4 step Y1'!G140 -> 225 | L18: ='Formular 4 step Y1'!G141 -> 226 | M18: ='Formular 4 step Y1'!G141 -> 226 | N18: ='Formular 4 step Y1'!H139 -> 218 | O18: ='Formular 4 step Y1'!H140 -> 219 | P18: ='Formular 4 step Y1'!H141 -> 220 | Q18: ='Formular 4 step Y1'!H141 -> 220
A19: ยิปซัม ธรรมดา 15 มม. ขอบลาด | B19: ='Formular 4 step Y1'!E838 -> 239 | C19: ='Formular 4 step Y1'!E839 -> 240 | D19: ='Formular 4 step Y1'!E840 -> 241 | E19: ='Formular 4 step Y1'!E841 -> 242 | F19: ='Formular 4 step Y1'!F838 -> 245 | G19: ='Formular 4 step Y1'!F839 -> 246 | H19: ='Formular 4 step Y1'!F840 -> 247 | I19: ='Formular 4 step Y1'!F841 -> 248 | J19: ='Formular 4 step Y1'!G838 -> 234 | K19: ='Formular 4 step Y1'!G839 -> 235 | L19: ='Formular 4 step Y1'!G840 -> 236 | M19: ='Formular 4 step Y1'!G841 -> 237 | N19: ='Formular 4 step Y1'!H838 -> 224 | O19: ='Formular 4 step Y1'!H839 -> 225 | P19: ='Formular 4 step Y1'!H840 -> 226 | Q19: ='Formular 4 step Y1'!H841 -> 227
A20: ทนไฟ 12 มม. | B20: ='Formular 4 step Y1'!E164 -> 269 | C20: ='Formular 4 step Y1'!E165 -> 272 | D20: ='Formular 4 step Y1'!E166 -> 277 | E20: ='Formular 4 step Y1'!E167 -> 282 | F20: ='Formular 4 step Y1'!F164 -> 272 | G20: ='Formular 4 step Y1'!F165 -> 275 | H20: ='Formular 4 step Y1'!F166 -> 280 | I20: ='Formular 4 step Y1'!F167 -> 285 | J20: ='Formular 4 step Y1'!G164 -> 265 | K20: ='Formular 4 step Y1'!G165 -> 268 | L20: ='Formular 4 step Y1'!G166 -> 273 | M20: ='Formular 4 step Y1'!G167 -> 278 | N20: ='Formular 4 step Y1'!H164 -> 259 | O20: ='Formular 4 step Y1'!H165 -> 262 | P20: ='Formular 4 step Y1'!H166 -> 267 | Q20: ='Formular 4 step Y1'!H167 -> 272
A21: ทนไฟ 15 มม. | B21: ='Formular 4 step Y1'!E189 -> 312 | C21: ='Formular 4 step Y1'!E190 -> 315 | D21: ='Formular 4 step Y1'!E191 -> 320 | E21: ='Formular 4 step Y1'!E192 -> 325 | F21: ='Formular 4 step Y1'!F189 -> 318 | G21: ='Formular 4 step Y1'!F190 -> 321 | H21: ='Formular 4 step Y1'!F191 -> 326 | I21: ='Formular 4 step Y1'!F192 -> 331 | J21: ='Formular 4 step Y1'!G189 -> 305 | K21: ='Formular 4 step Y1'!G190 -> 308 | L21: ='Formular 4 step Y1'!G191 -> 313 | M21: ='Formular 4 step Y1'!G192 -> 318 | N21: ='Formular 4 step Y1'!H189 -> 293 | O21: ='Formular 4 step Y1'!H190 -> 296 | P21: ='Formular 4 step Y1'!H191 -> 301 | Q21: ='Formular 4 step Y1'!H192 -> 306
A22: ยิปซัมเฟล็กบอร์ด(ดัดโค้ง) 6 มม. 120*240 มม. | B22: ='Formular 4 step Y1'!E863 -> 190.57762 | C22: ='Formular 4 step Y1'!E864 -> 192.34223 | D22: ='Formular 4 step Y1'!E865 -> 197.63605 | E22: ='Formular 4 step Y1'!E866 -> 202.92987 | F22: ='Formular 4 step Y1'!F863 -> 193.27762 | G22: ='Formular 4 step Y1'!F864 -> 195.06723 | H22: ='Formular 4 step Y1'!F865 -> 200.43605 | I22: ='Formular 4 step Y1'!F866 -> 205.80487 | J22: ='Formular 4 step Y1'!G863 -> 187.87762 | K22: ='Formular 4 step Y1'!G864 -> 189.61723 | L22: ='Formular 4 step Y1'!G865 -> 194.83605 | M22: ='Formular 4 step Y1'!G866 -> 200.05487 | N22: ='Formular 4 step Y1'!H863 -> 183.01762 | O22: ='Formular 4 step Y1'!H864 -> 184.71223 | P22: ='Formular 4 step Y1'!H865 -> 189.79605 | Q22: ='Formular 4 step Y1'!H866 -> 194.87987
A23: อี่ซี่บอร์ท / คนอฟ | B23: ='Formular 4 step Y1'!E738 -> 105 | C23: ='Formular 4 step Y1'!E739 -> 106 | D23: ='Formular 4 step Y1'!E740 -> 107 | E23: ='Formular 4 step Y1'!E741 -> 108 | F23: ='Formular 4 step Y1'!F738 -> 105 | G23: ='Formular 4 step Y1'!F739 -> 106 | H23: ='Formular 4 step Y1'!F740 -> 107 | I23: ='Formular 4 step Y1'!F741 -> 108 | J23: ='Formular 4 step Y1'!G738 -> 105 | K23: ='Formular 4 step Y1'!G739 -> 106 | L23: ='Formular 4 step Y1'!G740 -> 107 | M23: ='Formular 4 step Y1'!G741 -> 108 | N23: ='Formular 4 step Y1'!H738 -> 105 | O23: ='Formular 4 step Y1'!H739 -> 106 | P23: ='Formular 4 step Y1'!H740 -> 107 | Q23: ='Formular 4 step Y1'!H741 -> 108
A24: อี่ซี่บอร์ท/คนอฟ ทนชื้น / ฟอล์ย | B24: ='Formular 4 step Y1'!E763 -> 162 | C24: ='Formular 4 step Y1'!E764 -> 163 | D24: ='Formular 4 step Y1'!E765 -> 164 | E24: ='Formular 4 step Y1'!E766 -> 165 | F24: ='Formular 4 step Y1'!F763 -> 162 | G24: ='Formular 4 step Y1'!F764 -> 163 | H24: ='Formular 4 step Y1'!F765 -> 164 | I24: ='Formular 4 step Y1'!F766 -> 165 | J24: ='Formular 4 step Y1'!G763 -> 162 | K24: ='Formular 4 step Y1'!G764 -> 163 | L24: ='Formular 4 step Y1'!G765 -> 164 | M24: ='Formular 4 step Y1'!G766 -> 165 | N24: ='Formular 4 step Y1'!H763 -> 162 | O24: ='Formular 4 step Y1'!H764 -> 163 | P24: ='Formular 4 step Y1'!H765 -> 164 | Q24: ='Formular 4 step Y1'!H766 -> 165
A25: เวเทอร์บล็อค W0 | B25: ='Formular 4 step Y1'!E788 -> 278 | C25: ='Formular 4 step Y1'!E789 -> 279 | D25: ='Formular 4 step Y1'!E790 -> 280 | E25: ='Formular 4 step Y1'!E791 -> 281 | F25: ='Formular 4 step Y1'!F788 -> 280 | G25: ='Formular 4 step Y1'!F789 -> 281 | H25: ='Formular 4 step Y1'!F790 -> 282 | I25: ='Formular 4 step Y1'!F791 -> 283 | J25: ='Formular 4 step Y1'!G788 -> 276 | K25: ='Formular 4 step Y1'!G789 -> 277 | L25: ='Formular 4 step Y1'!G790 -> 278 | M25: ='Formular 4 step Y1'!G791 -> 279 | N25: ='Formular 4 step Y1'!H788 -> 272 | O25: ='Formular 4 step Y1'!H789 -> 273 | P25: ='Formular 4 step Y1'!H790 -> 274 | Q25: ='Formular 4 step Y1'!H791 -> 275
A26: เวเทอร์บล็อค W1 | B26: ='Formular 4 step Y1'!E813 -> 435 | C26: ='Formular 4 step Y1'!E814 -> 436 | D26: ='Formular 4 step Y1'!E815 -> 437 | E26: ='Formular 4 step Y1'!E816 -> 438 | F26: ='Formular 4 step Y1'!F813 -> 437 | G26: ='Formular 4 step Y1'!F814 -> 438 | H26: ='Formular 4 step Y1'!F815 -> 439 | I26: ='Formular 4 step Y1'!F816 -> 440 | J26: ='Formular 4 step Y1'!G813 -> 433 | K26: ='Formular 4 step Y1'!G814 -> 434 | L26: ='Formular 4 step Y1'!G815 -> 435 | M26: ='Formular 4 step Y1'!G816 -> 436 | N26: ='Formular 4 step Y1'!H813 -> 429 | O26: ='Formular 4 step Y1'!H814 -> 430 | P26: ='Formular 4 step Y1'!H815 -> 431 | Q26: ='Formular 4 step Y1'!H816 -> 432
A27: ยิปซัมลดเสียงสะท้อน เอคโค่บล็อค (R1,R2,R8,S8) | B27: ='Formular 4 step Y1'!E214 -> 920 | C27: ='Formular 4 step Y1'!E215 -> 923 | D27: ='Formular 4 step Y1'!E216 -> 933 | E27: ='Formular 4 step Y1'!E217 -> 943 | F27: ='Formular 4 step Y1'!F214 -> 924 | G27: ='Formular 4 step Y1'!F215 -> 927 | H27: ='Formular 4 step Y1'!F216 -> 937 | I27: ='Formular 4 step Y1'!F217 -> 947 | J27: ='Formular 4 step Y1'!G214 -> 917 | K27: ='Formular 4 step Y1'!G215 -> 920 | L27: ='Formular 4 step Y1'!G216 -> 930 | M27: ='Formular 4 step Y1'!G217 -> 940 | N27: ='Formular 4 step Y1'!H214 -> 910 | O27: ='Formular 4 step Y1'!H215 -> 913 | P27: ='Formular 4 step Y1'!H216 -> 923 | Q27: ='Formular 4 step Y1'!H217 -> 933
A28: Paper touch ลวดลาย 60*60*8 mm. | B28: ='Formular 4 step Y1'!E239 -> 22.267906 | C28: ='Formular 4 step Y1'!E240 -> 23 | D28: ='Formular 4 step Y1'!E241 -> 24 | E28: ='Formular 4 step Y1'!E242 -> 25 | F28: ='Formular 4 step Y1'!F239 -> 22.267906 | G28: ='Formular 4 step Y1'!F240 -> 23 | H28: ='Formular 4 step Y1'!F241 -> 24 | I28: ='Formular 4 step Y1'!F242 -> 25 | J28: ='Formular 4 step Y1'!G239 -> 22.267906 | K28: ='Formular 4 step Y1'!G240 -> 23 | L28: ='Formular 4 step Y1'!G241 -> 24 | M28: ='Formular 4 step Y1'!G242 -> 25 | N28: ='Formular 4 step Y1'!H239 -> 22.267906 | O28: ='Formular 4 step Y1'!H240 -> 23 | P28: ='Formular 4 step Y1'!H241 -> 24 | Q28: ='Formular 4 step Y1'!H242 -> 25
A29: Paper touch หยาดเพชร 60*60*8 mm. | B29: ='Formular 4 step Y1'!E264 -> 19.866612 | C29: ='Formular 4 step Y1'!E265 -> 21 | D29: ='Formular 4 step Y1'!E266 -> 22 | E29: ='Formular 4 step Y1'!E267 -> 23 | F29: ='Formular 4 step Y1'!F264 -> 19.866612 | G29: ='Formular 4 step Y1'!F265 -> 21 | H29: ='Formular 4 step Y1'!F266 -> 22 | I29: ='Formular 4 step Y1'!F267 -> 23 | J29: ='Formular 4 step Y1'!G264 -> 19.866612 | K29: ='Formular 4 step Y1'!G265 -> 21 | L29: ='Formular 4 step Y1'!G266 -> 22 | M29: ='Formular 4 step Y1'!G267 -> 23 | N29: ='Formular 4 step Y1'!H264 -> 19.866612 | O29: ='Formular 4 step Y1'!H265 -> 21 | P29: ='Formular 4 step Y1'!H266 -> 22 | Q29: ='Formular 4 step Y1'!H267 -> 23
A30: Paper touch หยาดเพชร 60*60*8 mm. กันร้อน | B30: ='Formular 4 step Y1'!E289 -> 25.329818 | C30: ='Formular 4 step Y1'!E290 -> 26 | D30: ='Formular 4 step Y1'!E291 -> 27 | E30: ='Formular 4 step Y1'!E292 -> 28 | F30: ='Formular 4 step Y1'!F289 -> 25.329818 | G30: ='Formular 4 step Y1'!F290 -> 26 | H30: ='Formular 4 step Y1'!F291 -> 27 | I30: ='Formular 4 step Y1'!F292 -> 28 | J30: ='Formular 4 step Y1'!G289 -> 25.329818 | K30: ='Formular 4 step Y1'!G290 -> 26 | L30: ='Formular 4 step Y1'!G291 -> 27 | M30: ='Formular 4 step Y1'!G292 -> 28 | N30: ='Formular 4 step Y1'!H289 -> 25.329818 | O30: ='Formular 4 step Y1'!H290 -> 26 | P30: ='Formular 4 step Y1'!H291 -> 27 | Q30: ='Formular 4 step Y1'!H292 -> 28
A31: Color touch สีมุก/สีเพชร 60x60*9 mm. | B31: ='Formular 4 step Y1'!E313 -> 23 | C31: ='Formular 4 step Y1'!E314 -> 24 | D31: ='Formular 4 step Y1'!E315 -> 25 | E31: ='Formular 4 step Y1'!E316 -> 26 | F31: ='Formular 4 step Y1'!F313 -> 23 | G31: ='Formular 4 step Y1'!F314 -> 24 | H31: ='Formular 4 step Y1'!F315 -> 25 | I31: ='Formular 4 step Y1'!F316 -> 26 | J31: ='Formular 4 step Y1'!G313 -> 23 | K31: ='Formular 4 step Y1'!G314 -> 24 | L31: ='Formular 4 step Y1'!G315 -> 25 | M31: ='Formular 4 step Y1'!G316 -> 26 | N31: ='Formular 4 step Y1'!H313 -> 23 | O31: ='Formular 4 step Y1'!H314 -> 24 | P31: ='Formular 4 step Y1'!H315 -> 25 | Q31: ='Formular 4 step Y1'!H316 -> 26
A32: Color touch สีมุก/สีเพชร 60x120*9 mm. | B32: ='Formular 4 step Y1'!E338 -> 46 | C32: ='Formular 4 step Y1'!E339 -> 47 | D32: ='Formular 4 step Y1'!E340 -> 48 | E32: ='Formular 4 step Y1'!E341 -> 50 | F32: ='Formular 4 step Y1'!F338 -> 46 | G32: ='Formular 4 step Y1'!F339 -> 47 | H32: ='Formular 4 step Y1'!F340 -> 48 | I32: ='Formular 4 step Y1'!F341 -> 50 | J32: ='Formular 4 step Y1'!G338 -> 46 | K32: ='Formular 4 step Y1'!G339 -> 47 | L32: ='Formular 4 step Y1'!G340 -> 48 | M32: ='Formular 4 step Y1'!G341 -> 50 | N32: ='Formular 4 step Y1'!H338 -> 46 | O32: ='Formular 4 step Y1'!H339 -> 47 | P32: ='Formular 4 step Y1'!H340 -> 48 | Q32: ='Formular 4 step Y1'!H341 -> 50
A33: Color touch สีมุก/สีเพชร 60x120*12 mm. | B33: ='Formular 4 step Y1'!E888 -> 46.802609 | C33: ='Formular 4 step Y1'!E889 -> 47.5 | D33: ='Formular 4 step Y1'!E890 -> 48.090754 | E33: ='Formular 4 step Y1'!E891 -> 49.378899 | F33: ='Formular 4 step Y1'!F888 -> 46.802609 | G33: ='Formular 4 step Y1'!F889 -> 47.5 | H33: ='Formular 4 step Y1'!F890 -> 48.090754 | I33: ='Formular 4 step Y1'!F891 -> 49.378899 | J33: ='Formular 4 step Y1'!G888 -> 46.802609 | K33: ='Formular 4 step Y1'!G889 -> 47.5 | L33: ='Formular 4 step Y1'!G890 -> 48.090754 | M33: ='Formular 4 step Y1'!G891 -> 49.378899 | N33: ='Formular 4 step Y1'!H888 -> 46.802609 | O33: ='Formular 4 step Y1'!H889 -> 47.5 | P33: ='Formular 4 step Y1'!H890 -> 48.090754 | Q33: ='Formular 4 step Y1'!H891 -> 49.378899
A34: Color touch สีมุก/สีเพชร 60x60*9 mm. ทนชื้น | B34: ='Formular 4 step Y1'!E363 -> 28 | C34: ='Formular 4 step Y1'!E364 -> 29 | D34: ='Formular 4 step Y1'!E365 -> 31 | E34: ='Formular 4 step Y1'!E366 -> 32 | F34: ='Formular 4 step Y1'!F363 -> 28 | G34: ='Formular 4 step Y1'!F364 -> 29 | H34: ='Formular 4 step Y1'!F365 -> 31 | I34: ='Formular 4 step Y1'!F366 -> 32 | J34: ='Formular 4 step Y1'!G363 -> 28 | K34: ='Formular 4 step Y1'!G364 -> 29 | L34: ='Formular 4 step Y1'!G365 -> 31 | M34: ='Formular 4 step Y1'!G366 -> 32 | N34: ='Formular 4 step Y1'!H363 -> 28 | O34: ='Formular 4 step Y1'!H364 -> 29 | P34: ='Formular 4 step Y1'!H365 -> 31 | Q34: ='Formular 4 step Y1'!H366 -> 32
A35: Color touch สีมุก/สีเพชร 60x120*9 mm. ทนชื้น | B35: ='Formular 4 step Y1'!E388 -> 57 | C35: ='Formular 4 step Y1'!E389 -> 58 | D35: ='Formular 4 step Y1'!E390 -> 59 | E35: ='Formular 4 step Y1'!E391 -> 61 | F35: ='Formular 4 step Y1'!F388 -> 57 | G35: ='Formular 4 step Y1'!F389 -> 58 | H35: ='Formular 4 step Y1'!F390 -> 59 | I35: ='Formular 4 step Y1'!F391 -> 61 | J35: ='Formular 4 step Y1'!G388 -> 57 | K35: ='Formular 4 step Y1'!G389 -> 58 | L35: ='Formular 4 step Y1'!G390 -> 59 | M35: ='Formular 4 step Y1'!Q391 -> 62 | N35: ='Formular 4 step Y1'!H388 -> 57 | O35: ='Formular 4 step Y1'!H389 -> 58 | P35: ='Formular 4 step Y1'!H390 -> 59 | Q35: ='Formular 4 step Y1'!H391 -> 61
A36: Color touch สีมุก/สีเพชร 60x120*12 mm. ทนชื้น | B36: ='Formular 4 step Y1'!D913 -> 63.551024 | C36: ='Formular 4 step Y1'!D914 -> 64.5 | D36: ='Formular 4 step Y1'!D915 -> 65.300135 | E36: ='Formular 4 step Y1'!D916 -> 67.049246 | F36: ='Formular 4 step Y1'!F913 -> 63.442024 | G36: ='Formular 4 step Y1'!F914 -> 64.5 | H36: ='Formular 4 step Y1'!F915 -> 65.188135 | I36: ='Formular 4 step Y1'!F916 -> 66.934246 | J36: ='Formular 4 step Y1'!G913 -> 63.442024 | K36: ='Formular 4 step Y1'!G914 -> 64.5 | L36: ='Formular 4 step Y1'!G915 -> 65.188135 | M36: ='Formular 4 step Y1'!G916 -> 66.934246 | N36: ='Formular 4 step Y1'!H913 -> 63.442024 | O36: ='Formular 4 step Y1'!H914 -> 64.5 | P36: ='Formular 4 step Y1'!H915 -> 65.188135 | Q36: ='Formular 4 step Y1'!H916 -> 66.934246
A37: เซิฟบอร์ด ขนาด 30 ซม. | B37: ='Formular 4 step Y1'!E413 -> 189 | C37: ='Formular 4 step Y1'!E414 -> 190 | D37: ='Formular 4 step Y1'!E415 -> 195 | E37: ='Formular 4 step Y1'!E416 -> 200 | F37: ='Formular 4 step Y1'!F413 -> 189 | G37: ='Formular 4 step Y1'!F414 -> 190 | H37: ='Formular 4 step Y1'!F415 -> 195 | I37: ='Formular 4 step Y1'!F416 -> 200 | J37: ='Formular 4 step Y1'!G413 -> 189 | K37: ='Formular 4 step Y1'!G414 -> 190 | L37: ='Formular 4 step Y1'!G415 -> 195 | M37: ='Formular 4 step Y1'!G416 -> 200 | N37: ='Formular 4 step Y1'!H413 -> 189 | O37: ='Formular 4 step Y1'!H414 -> 190 | P37: ='Formular 4 step Y1'!H415 -> 195 | Q37: ='Formular 4 step Y1'!H416 -> 200
